Workbook
Name ADD_Dint_L63_Time: '[1]Ladder Instructions'!#REF!
Name ADD_DINT_L75_Mem_20: '[1]Ladder Instructions'!#REF!
Name ADD_Dint_L75_STTime_20: '[1]Structured Text'!#REF!
Name ADD_Dint_L75_Time_20: '[1]Ladder Instructions'!#REF!
Name ADD_DINT_Mem: '[1]Ladder Instructions'!#REF!
Name ADD_DINT_Mem_18: '[1]Ladder Instructions'!#REF!
Name ADD_Real_L63_Time: '[1]Ladder Instructions'!#REF!
Name ADD_Real_L75_Mem_20: '[1]Ladder Instructions'!#REF!
Name ADD_Real_L75_Time_20: '[1]Ladder Instructions'!#REF!
Name ADD_Real_Mem: '[1]Ladder Instructions'!#REF!
Name array_indexes: Introduction!#REF!
Name array_indexes: [2]Introduction!#REF!
Name Array_Subscript_L75_Mem_20: #REF!
Name Array_Subscript_L75_Time_20: #REF!
Name ArrayTime: #REF!
Name Conv_Dint_Int: #REF!
Name Conv_Dint_Int_Mem: #REF!
Name Conv_Dint_Real: #REF!
Name Conv_Dint_Real_Mem: #REF!
Name Conv_Int_Dint: #REF!
Name Conv_Int_Dint_Mem: #REF!
Name Conv_Real_Dint: #REF!
Name Conv_Real_Dint_Mem: #REF!
Name CPT_L63_Time: '[1]Ladder Instructions'!#REF!
Name CPT_L75_Mem_20: '[1]Ladder Instructions'!#REF!
Name CPT_L75_Time_20: '[1]Ladder Instructions'!#REF!
Name CPT_Mem: '[1]Ladder Instructions'!#REF!
Name Data_Conversions: Introduction!#REF!
Name Data_Conversions: [2]Introduction!#REF!
Name data_conversions_time: Introduction!#REF!
Name data_conversions_time: [2]Introduction!#REF!
Name Function_Block_Elements: Introduction!#REF!
Name Function_Block_Elements: [2]Introduction!#REF!
Name ladder_logic_instructions: Introduction!#REF!
Name ladder_logic_instructions: [2]Introduction!#REF!
Name LadderInstructionTimes: Introduction!#REF!
Name LadderInstructionTimes: [2]Introduction!#REF!
Name Motion_Tasks: Introduction!#REF!
Name Motion_Tasks: [2]Introduction!#REF!
Name SFCs: [1]SFC!#REF!
Name structured_text_constructs: Introduction!#REF!
Name structured_text_constructs: [2]Introduction!#REF!

Sheet Introduction
A1: Kinetix 5100 Servo Drive Parameters Reference Data
A4: About This Publication | B4: This publication lists the parameters for Kinetix 5100 EtherNet/IP Indexing Servo Drives
B5: For more information see: Kinetix 5100 EtherNet/IP Indexing Servo Drives User Manual
B6: 2198-UM004
A8: Important: Rockwell Automation is not responsible for any content or format changes made by other parties after downloading this spreadsheet file. The original file can be re-downloaded at any time.
A10: TIP: When you search for information in a spreadsheet, set the search options to search the workbook, rather than the current sheet (tab).
A12: Allen-Bradley, expanding human possibility, and Rockwell Automation are trademarks of Rockwell Automation, Inc. EtherNet/IP is a trademark of ODVA, Inc. Trademarks not belonging to Rockwell Automation are property of their respective companies.

Sheet Summary of Changes
A1: Summary of Changes
A3: Date | B3: Changes
A5: September 2020 | B5: First release as an Excel spreadsheet
A6: November 2020 | B6: Added P1.022 to 'Motion' group.
B7: Deleted ▲Set when servo off of P1.045.
B8: Changed the name of ID113(P0.054) from SystemVariableMonitorFilterTime to SystemVariableMonitorLowerLimit and changed the comments.
B9: Added ID 685 ZPhaseSourceOfHoming to 'General' group.
B10: Added ID 686 FullClosedLoopMonitoringConfiguration to 'General' group.
B11: Changed the type and min/max value of ID183 P1.103, ID131 P1.019.
B12: Changed the type and min/max value of ID331 P5.039, ID131 P1.110
B13: Changed ID 675 (P1.032) max value to 0x0030, min value to 0x0010, change Y=3 comments.
B14: Changed the unit from 0.01mH to 0.00001H of PM.036.
B15: Deleted P1.084.
B16: Added new parameter 69…79,81, 98, and 99.
B17: Changed max value of ID 60…65 (P0.035…P0.039) from 684 to 687.
B18: Changed type of PN.044 from UINT to DINT, min/max/default value and unit.
... B24: Changed the default of P1.053 to 0.
A25: June 2021 | B25: Added and edited parameter and ranges for rotary motors
B26: Added and edited parameter and ranges for linear motors
B27: Edited min max vlaues of muliple parameters to support different motors
B28: This is the first revision as publication 2198-RD002A-EN-P.

Sheet 1 - Motor
A1: Kinetix 5100 Servo Drive Parameters For more information see:
A2: Kinetix 5100 Servo Drive User Manual, publication 2198-UM004
A4: ID | B4: Name | C4: Control Mode | D4: Min. | E4: Max. | F4: Default Value | G4: Precision | H4: Units | I4: Data Type | J4: Comments | K4: Groups | L4: Read-only | M4: Set When Servo Off | N4: Valid After Power Cycle | O4: Volatile Parameter | P4: Parameter Number
A5: 1 | B5: =IF(VLOOKUP($A5,Sheet1!$A$3:$AW$699,20,FALSE)="","",VLOOKUP($A5,Sheet1!$A$3:$AW$699,20,FALSE)) -> MotorType | C5: =IF(VLOOKUP($A5,Sheet1!$A$3:$AW$699,25,FALSE)="","",VLOOKUP($A5,Sheet1!$A$3:$AW$699,25,FALSE)) -> All | D5: =IF(VLOOKUP($A5,Sheet1!$A$3:$AW$699,15,FALSE)="","",VLOOKUP($A5,Sheet1!$A$3:$AW$699,15,FALSE)) -> 0 | E5: =IF(VLOOKUP($A5,Sheet1!$A$3:$AW$699,16,FALSE)="","",VLOOKUP($A5,Sheet1!$A$3:$AW$699,16,FALSE)) -> 3 | F5: =IF(VLOOKUP($A5,Sheet1!$A$3:$AW$699,17,FALSE)="","",VLOOKUP($A5,Sheet1!$A$3:$AW$699,17,FALSE)) -> 0 | G5: =IF(VLOOKUP($A5,Sheet1!$A$3:$AW$699,18,FALSE)="","",VLOOKUP($A5,Sheet1!$A$3:$AW$699,18,FALSE)) | H5: =IF(VLOOKUP($A5,Sheet1!$A$3:$AW$699,19,FALSE)="","",VLOOKUP($A5,Sheet1!$A$3:$AW$699,19,FALSE)) | I5: =IF(VLOOKUP($A5,Sheet1!$A$3:$AW$699,5,FALSE)="","",VLOOKUP($A5,Sheet1!$A$3:$AW$699,5,FALSE)) -> USINT | J5: Motor Type 0 = Rotary Permanent Magnet 1 = Reserved 2 = Linear Motor. 3 = Induction Machine | K5: 1-Motor 11-System | L5: =IF(VLOOKUP($A5,Sheet1!$A$3:$AW$699,7,FALSE)="★","x","") | M5: =IF(VLOOKUP($A5,Sheet1!$A$3:$AW$699,8,FALSE)="▲","x","") -> x | N5: =IF(VLOOKUP($A5,Sheet1!$A$3:$AW$699,9,FALSE)="●","x","") -> x | O5: =IF(VLOOKUP($A5,Sheet1!$A$3:$AW$699,10,FALSE)="■","x","") | P5: =IF(VLOOKUP($A5,Sheet1!$A$3:$AW$699,2,FALSE)="","",VLOOKUP($A5,Sheet1!$A$3:$AW$699,2,FALSE)) -> PM.000
A6: 2 | B6: =IF(VLOOKUP($A6,Sheet1!$A$3:$AW$699,20,FALSE)="","",VLOOKUP($A6,Sheet1!$A$3:$AW$699,20,FALSE)) -> MotorCatalogNumber | C6: =IF(VLOOKUP($A6,Sheet1!$A$3:$AW$699,25,FALSE)="","",VLOOKUP($A6,Sheet1!$A$3:$AW$699,25,FALSE)) -> All | D6: =IF(VLOOKUP($A6,Sheet1!$A$3:$AW$699,15,FALSE)="","",VLOOKUP($A6,Sheet1!$A$3:$AW$699,15,FALSE)) | E6: =IF(VLOOKUP($A6,Sheet1!$A$3:$AW$699,16,FALSE)="","",VLOOKUP($A6,Sheet1!$A$3:$AW$699,16,FALSE)) | F6: =IF(VLOOKUP($A6,Sheet1!$A$3:$AW$699,17,FALSE)="","",VLOOKUP($A6,Sheet1!$A$3:$AW$699,17,FALSE)) | G6: =IF(VLOOKUP($A6,Sheet1!$A$3:$AW$699,18,FALSE)="","",VLOOKUP($A6,Sheet1!$A$3:$AW$699,18,FALSE)) | H6: =IF(VLOOKUP($A6,Sheet1!$A$3:$AW$699,19,FALSE)="","",VLOOKUP($A6,Sheet1!$A$3:$AW$699,19,FALSE)) | I6: =IF(VLOOKUP($A6,Sheet1!$A$3:$AW$699,5,FALSE)="","",VLOOKUP($A6,Sheet1!$A$3:$AW$699,5,FALSE)) -> SHORT_STRING | J6: Motor Catalog Number [0]-[15] | K6: 1-Motor 11-System | L6: =IF(VLOOKUP($A6,Sheet1!$A$3:$AW$699,7,FALSE)="★","x","") | M6: =IF(VLOOKUP($A6,Sheet1!$A$3:$AW$699,8,FALSE)="▲","x","") -> x | N6: =IF(VLOOKUP($A6,Sheet1!$A$3:$AW$699,9,FALSE)="●","x","") | O6: =IF(VLOOKUP($A6,Sheet1!$A$3:$AW$699,10,FALSE)="■","x","") | P6: =IF(VLOOKUP($A6,Sheet1!$A$3:$AW$699,2,FALSE)="","",VLOOKUP($A6,Sheet1!$A$3:$AW$699,2,FALSE)) -> PN.010
A7: 3 | B7: =IF(VLOOKUP($A7,Sheet1!$A$3:$AW$699,20,FALSE)="","",VLOOKUP($A7,Sheet1!$A$3:$AW$699,20,FALSE)) -> MotorManufacturer | C7: =IF(VLOOKUP($A7,Sheet1!$A$3:$AW$699,25,FALSE)="","",VLOOKUP($A7,Sheet1!$A$3:$AW$699,25,FALSE)) -> All | D7: =IF(VLOOKUP($A7,Sheet1!$A$3:$AW$699,15,FALSE)="","",VLOOKUP($A7,Sheet1!$A$3:$AW$699,15,FALSE)) | E7: =IF(VLOOKUP($A7,Sheet1!$A$3:$AW$699,16,FALSE)="","",VLOOKUP($A7,Sheet1!$A$3:$AW$699,16,FALSE)) | F7: =IF(VLOOKUP($A7,Sheet1!$A$3:$AW$699,17,FALSE)="","",VLOOKUP($A7,Sheet1!$A$3:$AW$699,17,FALSE)) | G7: =IF(VLOOKUP($A7,Sheet1!$A$3:$AW$699,18,FALSE)="","",VLOOKUP($A7,Sheet1!$A$3:$AW$699,18,FALSE)) | H7: =IF(VLOOKUP($A7,Sheet1!$A$3:$AW$699,19,FALSE)="","",VLOOKUP($A7,Sheet1!$A$3:$AW$699,19,FALSE)) | I7: =IF(VLOOKUP($A7,Sheet1!$A$3:$AW$699,5,FALSE)="","",VLOOKUP($A7,Sheet1!$A$3:$AW$699,5,FALSE)) -> SHORT_STRING | J7: Motor Manufacturer's Name [0]-[31] | K7: 1-Motor | L7: =IF(VLOOKUP($A7,Sheet1!$A$3:$AW$699,7,FALSE)="★","x","") -> x | M7: =IF(VLOOKUP($A7,Sheet1!$A$3:$AW$699,8,FALSE)="▲","x","") | N7: =IF(VLOOKUP($A7,Sheet1!$A$3:$AW$699,9,FALSE)="●","x","") | O7: =IF(VLOOKUP($A7,Sheet1!$A$3:$AW$699,10,FALSE)="■","x","") | P7: =IF(VLOOKUP($A7,Sheet1!$A$3:$AW$699,2,FALSE)="","",VLOOKUP($A7,Sheet1!$A$3:$AW$699,2,FALSE))
A8: 4 | B8: =IF(VLOOKUP($A8,Sheet1!$A$3:$AW$699,20,FALSE)="","",VLOOKUP($A8,Sheet1!$A$3:$AW$699,20,FALSE)) -> MotorRatedContinuousCurrent | C8: =IF(VLOOKUP($A8,Sheet1!$A$3:$AW$699,25,FALSE)="","",VLOOKUP($A8,Sheet1!$A$3:$AW$699,25,FALSE)) -> All | D8: =IF(VLOOKUP($A8,Sheet1!$A$3:$AW$699,15,FALSE)="","",VLOOKUP($A8,Sheet1!$A$3:$AW$699,15,FALSE)) -> 0 | E8: =IF(VLOOKUP($A8,Sheet1!$A$3:$AW$699,16,FALSE)="","",VLOOKUP($A8,Sheet1!$A$3:$AW$699,16,FALSE)) -> 65535 | F8: =IF(VLOOKUP($A8,Sheet1!$A$3:$AW$699,17,FALSE)="","",VLOOKUP($A8,Sheet1!$A$3:$AW$699,17,FALSE)) -> 260 | G8: =IF(VLOOKUP($A8,Sheet1!$A$3:$AW$699,18,FALSE)="","",VLOOKUP($A8,Sheet1!$A$3:$AW$699,18,FALSE)) -> 0.01 | H8: =IF(VLOOKUP($A8,Sheet1!$A$3:$AW$699,19,FALSE)="","",VLOOKUP($A8,Sheet1!$A$3:$AW$699,19,FALSE)) -> Amps (RMS) | I8: =IF(VLOOKUP($A8,Sheet1!$A$3:$AW$699,5,FALSE)="","",VLOOKUP($A8,Sheet1!$A$3:$AW$699,5,FALSE)) -> UINT | J8: Motor Rated Continuous Current The Min value must not be less than DriveRatedContinuousCurrent/8. e.g. The Rated Continuous Current of 2198-E1004-ERS is 2.60 A, so the min value is 33 (0.325 A). | K8: 1-Motor 11-System | L8: =IF(VLOOKUP($A8,Sheet1!$A$3:$AW$699,7,FALSE)="★","x","") | M8: =IF(VLOOKUP($A8,Sheet1!$A$3:$AW$699,8,FALSE)="▲","x","") -> x | N8: =IF(VLOOKUP($A8,Sheet1!$A$3:$AW$699,9,FALSE)="●","x","") -> x | O8: =IF(VLOOKUP($A8,Sheet1!$A$3:$AW$699,10,FALSE)="■","x","") | P8: =IF(VLOOKUP($A8,Sheet1!$A$3:$AW$699,2,FALSE)="","",VLOOKUP($A8,Sheet1!$A$3:$AW$699,2,FALSE)) -> PM.029
A9: 5 | B9: =IF(VLOOKUP($A9,Sheet1!$A$3:$AW$699,20,FALSE)="","",VLOOKUP($A9,Sheet1!$A$3:$AW$699,20,FALSE)) -> MotorRatedVoltage | C9: =IF(VLOOKUP($A9,Sheet1!$A$3:$AW$699,25,FALSE)="","",VLOOKUP($A9,Sheet1!$A$3:$AW$699,25,FALSE)) -> All | D9: =IF(VLOOKUP($A9,Sheet1!$A$3:$AW$699,15,FALSE)="","",VLOOKUP($A9,Sheet1!$A$3:$AW$699,15,FALSE)) -> 0 | E9: =IF(VLOOKUP($A9,Sheet1!$A$3:$AW$699,16,FALSE)="","",VLOOKUP($A9,Sheet1!$A$3:$AW$699,16,FALSE)) -> 65535 | F9: =IF(VLOOKUP($A9,Sheet1!$A$3:$AW$699,17,FALSE)="","",VLOOKUP($A9,Sheet1!$A$3:$AW$699,17,FALSE)) -> 220 | G9: =IF(VLOOKUP($A9,Sheet1!$A$3:$AW$699,18,FALSE)="","",VLOOKUP($A9,Sheet1!$A$3:$AW$699,18,FALSE)) | H9: =IF(VLOOKUP($A9,Sheet1!$A$3:$AW$699,19,FALSE)="","",VLOOKUP($A9,Sheet1!$A$3:$AW$699,19,FALSE)) -> Volts (RMS) | I9: =IF(VLOOKUP($A9,Sheet1!$A$3:$AW$699,5,FALSE)="","",VLOOKUP($A9,Sheet1!$A$3:$AW$699,5,FALSE)) -> UINT | J9: Motor Rated Base Voltage | K9: 1-Motor | L9: =IF(VLOOKUP($A9,Sheet1!$A$3:$AW$699,7,FALSE)="★","x","") | M9: =IF(VLOOKUP($A9,Sheet1!$A$3:$AW$699,8,FALSE)="▲","x","") -> x | N9: =IF(VLOOKUP($A9,Sheet1!$A$3:$AW$699,9,FALSE)="●","x","") | O9: =IF(VLOOKUP($A9,Sheet1!$A$3:$AW$699,10,FALSE)="■","x","") | P9: =IF(VLOOKUP($A9,Sheet1!$A$3:$AW$699,2,FALSE)="","",VLOOKUP($A9,Sheet1!$A$3:$AW$699,2,FALSE)) -> PM.065
A10: 6 | B10: =IF(VLOOKUP($A10,Sheet1!$A$3:$AW$699,20,FALSE)="","",VLOOKUP($A10,Sheet1!$A$3:$AW$699,20,FALSE)) -> MotorRatedOutputPower | C10: =IF(VLOOKUP($A10,Sheet1!$A$3:$AW$699,25,FALSE)="","",VLOOKUP($A10,Sheet1!$A$3:$AW$699,25,FALSE)) -> All | D10: =IF(VLOOKUP($A10,Sheet1!$A$3:$AW$699,15,FALSE)="","",VLOOKUP($A10,Sheet1!$A$3:$AW$699,15,FALSE)) -> 0 | E10: =IF(VLOOKUP($A10,Sheet1!$A$3:$AW$699,16,FALSE)="","",VLOOKUP($A10,Sheet1!$A$3:$AW$699,16,FALSE)) -> 655350 | F10: =IF(VLOOKUP($A10,Sheet1!$A$3:$AW$699,17,FALSE)="","",VLOOKUP($A10,Sheet1!$A$3:$AW$699,17,FALSE)) -> 40 | G10: =IF(VLOOKUP($A10,Sheet1!$A$3:$AW$699,18,FALSE)="","",VLOOKUP($A10,Sheet1!$A$3:$AW$699,18,FALSE)) -> 0.01 | H10: =IF(VLOOKUP($A10,Sheet1!$A$3:$AW$699,19,FALSE)="","",VLOOKUP($A10,Sheet1!$A$3:$AW$699,19,FALSE)) -> kW | I10: =IF(VLOOKUP($A10,Sheet1!$A$3:$AW$699,5,FALSE)="","",VLOOKUP($A10,Sheet1!$A$3:$AW$699,5,FALSE)) -> UDINT | J10: Motor Rated Output Power at Rated Frequency | K10: 1-Motor | L10: =IF(VLOOKUP($A10,Sheet1!$A$3:$AW$699,7,FALSE)="★","x","") | M10: =IF(VLOOKUP($A10,Sheet1!$A$3:$AW$699,8,FALSE)="▲","x","") | N10: =IF(VLOOKUP($A10,Sheet1!$A$3:$AW$699,9,FALSE)="●","x","") | O10: =IF(VLOOKUP($A10,Sheet1!$A$3:$AW$699,10,FALSE)="■","x","") | P10: =IF(VLOOKUP($A10,Sheet1!$A$3:$AW$699,2,FALSE)="","",VLOOKUP($A10,Sheet1!$A$3:$AW$699,2,FALSE)) -> PM.067
A11: 7 | B11: =IF(VLOOKUP($A11,Sheet1!$A$3:$AW$699,20,FALSE)="","",VLOOKUP($A11,Sheet1!$A$3:$AW$699,20,FALSE)) -> MotorRatedWindingTemperature | C11: =IF(VLOOKUP($A11,Sheet1!$A$3:$AW$699,25,FALSE)="","",VLOOKUP($A11,Sheet1!$A$3:$AW$699,25,FALSE)) -> All | D11: =IF(VLOOKUP($A11,Sheet1!$A$3:$AW$699,15,FALSE)="","",VLOOKUP($A11,Sheet1!$A$3:$AW$699,15,FALSE)) -> 0 | E11: =IF(VLOOKUP($A11,Sheet1!$A$3:$AW$699,16,FALSE)="","",VLOOKUP($A11,Sheet1!$A$3:$AW$699,16,FALSE)) -> 100 | F11: =IF(VLOOKUP($A11,Sheet1!$A$3:$AW$699,17,FALSE)="","",VLOOKUP($A11,Sheet1!$A$3:$AW$699,17,FALSE)) -> 80 | G11: =IF(VLOOKUP($A11,Sheet1!$A$3:$AW$699,18,FALSE)="","",VLOOKUP($A11,Sheet1!$A$3:$AW$699,18,FALSE)) | H11: =IF(VLOOKUP($A11,Sheet1!$A$3:$AW$699,19,FALSE)="","",VLOOKUP($A11,Sheet1!$A$3:$AW$699,19,FALSE)) -> oC | I11: =IF(VLOOKUP($A11,Sheet1!$A$3:$AW$699,5,FALSE)="","",VLOOKUP($A11,Sheet1!$A$3:$AW$699,5,FALSE)) -> UINT | J11: Motor Rated Winding Temperature | K11: 1-Motor | L11: =IF(VLOOKUP($A11,Sheet1!$A$3:$AW$699,7,FALSE)="★","x","") -> x | M11: =IF(VLOOKUP($A11,Sheet1!$A$3:$AW$699,8,FALSE)="▲","x","") | N11: =IF(VLOOKUP($A11,Sheet1!$A$3:$AW$699,9,FALSE)="●","x","") | O11: =IF(VLOOKUP($A11,Sheet1!$A$3:$AW$699,10,FALSE)="■","x","") | P11: =IF(VLOOKUP($A11,Sheet1!$A$3:$AW$699,2,FALSE)="","",VLOOKUP($A11,Sheet1!$A$3:$AW$699,2,FALSE))
A12: 8 | B12: =IF(VLOOKUP($A12,Sheet1!$A$3:$AW$699,20,FALSE)="","",VLOOKUP($A12,Sheet1!$A$3:$AW$699,20,FALSE)) -> MotorMaxSpeed | C12: =IF(VLOOKUP($A12,Sheet1!$A$3:$AW$699,25,FALSE)="","",VLOOKUP($A12,Sheet1!$A$3:$AW$699,25,FALSE)) -> All | D12: =IF(VLOOKUP($A12,Sheet1!$A$3:$AW$699,15,FALSE)="","",VLOOKUP($A12,Sheet1!$A$3:$AW$699,15,FALSE)) -> 0 | E12: =IF(VLOOKUP($A12,Sheet1!$A$3:$AW$699,16,FALSE)="","",VLOOKUP($A12,Sheet1!$A$3:$AW$699,16,FALSE)) -> 28500 | F12: =IF(VLOOKUP($A12,Sheet1!$A$3:$AW$699,17,FALSE)="","",VLOOKUP($A12,Sheet1!$A$3:$AW$699,17,FALSE)) -> 8000 | G12: =IF(VLOOKUP($A12,Sheet1!$A$3:$AW$699,18,FALSE)="","",VLOOKUP($A12,Sheet1!$A$3:$AW$699,18,FALSE)) | H12: =IF(VLOOKUP($A12,Sheet1!$A$3:$AW$699,19,FALSE)="","",VLOOKUP($A12,Sheet1!$A$3:$AW$699,19,FALSE)) -> RPM | I12: =IF(VLOOKUP($A12,Sheet1!$A$3:$AW$699,5,FALSE)="","",VLOOKUP($A12,Sheet1!$A$3:$AW$699,5,FALSE)) -> UINT | J12: Maximum allowed motor speed | K12: 1-Motor | L12: =IF(VLOOKUP($A12,Sheet1!$A$3:$AW$699,7,FALSE)="★","x","") | M12: =IF(VLOOKUP($A12,Sheet1!$A$3:$AW$699,8,FALSE)="▲","x","") -> x | N12: =IF(VLOOKUP($A12,Sheet1!$A$3:$AW$699,9,FALSE)="●","x","") -> x | O12: =IF(VLOOKUP($A12,Sheet1!$A$3:$AW$699,10,FALSE)="■","x","") | P12: =IF(VLOOKUP($A12,Sheet1!$A$3:$AW$699,2,FALSE)="","",VLOOKUP($A12,Sheet1!$A$3:$AW$699,2,FALSE)) -> PM.032
A13: 9 | B13: =IF(VLOOKUP($A13,Sheet1!$A$3:$AW$699,20,FALSE)="","",VLOOKUP($A13,Sheet1!$A$3:$AW$699,20,FALSE)) -> RotaryMotorPoles | C13: =IF(VLOOKUP($A13,Sheet1!$A$3:$AW$699,25,FALSE)="","",VLOOKUP($A13,Sheet1!$A$3:$AW$699,25,FALSE)) -> All | D13: =IF(VLOOKUP($A13,Sheet1!$A$3:$AW$699,15,FALSE)="","",VLOOKUP($A13,Sheet1!$A$3:$AW$699,15,FALSE)) -> 0 | E13: =IF(VLOOKUP($A13,Sheet1!$A$3:$AW$699,16,FALSE)="","",VLOOKUP($A13,Sheet1!$A$3:$AW$699,16,FALSE)) -> 500 | F13: =IF(VLOOKUP($A13,Sheet1!$A$3:$AW$699,17,FALSE)="","",VLOOKUP($A13,Sheet1!$A$3:$AW$699,17,FALSE)) -> 10 | G13: =IF(VLOOKUP($A13,Sheet1!$A$3:$AW$699,18,FALSE)="","",VLOOKUP($A13,Sheet1!$A$3:$AW$699,18,FALSE)) | H13: =IF(VLOOKUP($A13,Sheet1!$A$3:$AW$699,19,FALSE)="","",VLOOKUP($A13,Sheet1!$A$3:$AW$699,19,FALSE)) -> pole | I13: =IF(VLOOKUP($A13,Sheet1!$A$3:$AW$699,5,FALSE)="","",VLOOKUP($A13,Sheet1!$A$3:$AW$699,5,FALSE)) -> UINT | J13: Number of poles in the motor | K13: 1-Motor 11-System | L13: =IF(VLOOKUP($A13,Sheet1!$A$3:$AW$699,7,FALSE)="★","x","") | M13: =IF(VLOOKUP($A13,Sheet1!$A$3:$AW$699,8,FALSE)="▲","x","") -> x | N13: =IF(VLOOKUP($A13,Sheet1!$A$3:$AW$699,9,FALSE)="●","x","") -> x | O13: =IF(VLOOKUP($A13,Sheet1!$A$3:$AW$699,10,FALSE)="■","x","") | P13: =IF(VLOOKUP($A13,Sheet1!$A$3:$AW$699,2,FALSE)="","",VLOOKUP($A13,Sheet1!$A$3:$AW$699,2,FALSE)) -> PM.028
A14: 10 | B14: =IF(VLOOKUP($A14,Sheet1!$A$3:$AW$699,20,FALSE)="","",VLOOKUP($A14,Sheet1!$A$3:$AW$699,20,FALSE)) -> PMMotorTorqueConstant | C14: =IF(VLOOKUP($A14,Sheet1!$A$3:$AW$699,25,FALSE)="","",VLOOKUP($A14,Sheet1!$A$3:$AW$699,25,FALSE)) -> All | D14: =IF(VLOOKUP($A14,Sheet1!$A$3:$AW$699,15,FALSE)="","",VLOOKUP($A14,Sheet1!$A$3:$AW$699,15,FALSE)) -> 0 | E14: =IF(VLOOKUP($A14,Sheet1!$A$3:$AW$699,16,FALSE)="","",VLOOKUP($A14,Sheet1!$A$3:$AW$699,16,FALSE)) -> 65535 | F14: =IF(VLOOKUP($A14,Sheet1!$A$3:$AW$699,17,FALSE)="","",VLOOKUP($A14,Sheet1!$A$3:$AW$699,17,FALSE)) -> 0 | G14: =IF(VLOOKUP($A14,Sheet1!$A$3:$AW$699,18,FALSE)="","",VLOOKUP($A14,Sheet1!$A$3:$AW$699,18,FALSE)) -> 0.001 | H14: =IF(VLOOKUP($A14,Sheet1!$A$3:$AW$699,19,FALSE)="","",VLOOKUP($A14,Sheet1!$A$3:$AW$699,19,FALSE)) -> N-m/Amps (RMS) | I14: =IF(VLOOKUP($A14,Sheet1!$A$3:$AW$699,5,FALSE)="","",VLOOKUP($A14,Sheet1!$A$3:$AW$699,5,FALSE)) -> DINT | J14: Permanent Magnet Motor Torque Constant | K14: 1-Motor | L14: =IF(VLOOKUP($A14,Sheet1!$A$3:$AW$699,7,FALSE)="★","x","") | M14: =IF(VLOOKUP($A14,Sheet1!$A$3:$AW$699,8,FALSE)="▲","x","") -> x | N14: =IF(VLOOKUP($A14,Sheet1!$A$3:$AW$699,9,FALSE)="●","x","") | O14: =IF(VLOOKUP($A14,Sheet1!$A$3:$AW$699,10,FALSE)="■","x","") | P14: =IF(VLOOKUP($A14,Sheet1!$A$3:$AW$699,2,FALSE)="","",VLOOKUP($A14,Sheet1!$A$3:$AW$699,2,FALSE)) -> PM.033
A15: 11 | B15: =IF(VLOOKUP($A15,Sheet1!$A$3:$AW$699,20,FALSE)="","",VLOOKUP($A15,Sheet1!$A$3:$AW$699,20,FALSE)) -> RotaryMotorInertia | C15: =IF(VLOOKUP($A15,Sheet1!$A$3:$AW$699,25,FALSE)="","",VLOOKUP($A15,Sheet1!$A$3:$AW$699,25,FALSE)) -> All | D15: =IF(VLOOKUP($A15,Sheet1!$A$3:$AW$699,15,FALSE)="","",VLOOKUP($A15,Sheet1!$A$3:$AW$699,15,FALSE)) -> 0 | E15: =IF(VLOOKUP($A15,Sheet1!$A$3:$AW$699,16,FALSE)="","",VLOOKUP($A15,Sheet1!$A$3:$AW$699,16,FALSE)) -> 2147483647 | F15: =IF(VLOOKUP($A15,Sheet1!$A$3:$AW$699,17,FALSE)="","",VLOOKUP($A15,Sheet1!$A$3:$AW$699,17,FALSE)) -> 0 | G15: =IF(VLOOKUP($A15,Sheet1!$A$3:$AW$699,18,FALSE)="","",VLOOKUP($A15,Sheet1!$A$3:$AW$699,18,FALSE)) -> 0.001 | H15: =IF(VLOOKUP($A15,Sheet1!$A$3:$AW$699,19,FALSE)="","",VLOOKUP($A15,Sheet1!$A$3:$AW$699,19,FALSE)) -> 10^-4kg-m^2 | I15: =IF(VLOOKUP($A15,Sheet1!$A$3:$AW$699,5,FALSE)="","",VLOOKUP($A15,Sheet1!$A$3:$AW$699,5,FALSE)) -> DINT | J15: Rotary Motor Inertia | K15: 1-Motor | L15: =IF(VLOOKUP($A15,Sheet1!$A$3:$AW$699,7,FALSE)="★","x","") | M15: =IF(VLOOKUP($A15,Sheet1!$A$3:$AW$699,8,FALSE)="▲","x","") -> x | N15: =IF(VLOOKUP($A15,Sheet1!$A$3:$AW$699,9,FALSE)="●","x","") | O15: =IF(VLOOKUP($A15,Sheet1!$A$3:$AW$699,10,FALSE)="■","x","") | P15: =IF(VLOOKUP($A15,Sheet1!$A$3:$AW$699,2,FALSE)="","",VLOOKUP($A15,Sheet1!$A$3:$AW$699,2,FALSE)) -> PM.034
A16: 12 | B16: =IF(VLOOKUP($A16,Sheet1!$A$3:$AW$699,20,FALSE)="","",VLOOKUP($A16,Sheet1!$A$3:$AW$699,20,FALSE)) -> MotorRatedSpeed | C16: =IF(VLOOKUP($A16,Sheet1!$A$3:$AW$699,25,FALSE)="","",VLOOKUP($A16,Sheet1!$A$3:$AW$699,25,FALSE)) -> All | D16: =IF(VLOOKUP($A16,Sheet1!$A$3:$AW$699,15,FALSE)="","",VLOOKUP($A16,Sheet1!$A$3:$AW$699,15,FALSE)) -> 0 | E16: =IF(VLOOKUP($A16,Sheet1!$A$3:$AW$699,16,FALSE)="","",VLOOKUP($A16,Sheet1!$A$3:$AW$699,16,FALSE)) -> 28500 | F16: =IF(VLOOKUP($A16,Sheet1!$A$3:$AW$699,17,FALSE)="","",VLOOKUP($A16,Sheet1!$A$3:$AW$699,17,FALSE)) -> 8000 | G16: =IF(VLOOKUP($A16,Sheet1!$A$3:$AW$699,18,FALSE)="","",VLOOKUP($A16,Sheet1!$A$3:$AW$699,18,FALSE)) | H16: =IF(VLOOKUP($A16,Sheet1!$A$3:$AW$699,19,FALSE)="","",VLOOKUP($A16,Sheet1!$A$3:$AW$699,19,FALSE)) -> RPM | I16: =IF(VLOOKUP($A16,Sheet1!$A$3:$AW$699,5,FALSE)="","",VLOOKUP($A16,Sheet1!$A$3:$AW$699,5,FALSE)) -> INT | J16: Motor Rated Speed at Rated Frequency | K16: 1-Motor | L16: =IF(VLOOKUP($A16,Sheet1!$A$3:$AW$699,7,FALSE)="★","x","") | M16: =IF(VLOOKUP($A16,Sheet1!$A$3:$AW$699,8,FALSE)="▲","x","") -> x | N16: =IF(VLOOKUP($A16,Sheet1!$A$3:$AW$699,9,FALSE)="●","x","") -> x | O16: =IF(VLOOKUP($A16,Sheet1!$A$3:$AW$699,10,FALSE)="■","x","") | P16: =IF(VLOOKUP($A16,Sheet1!$A$3:$AW$699,2,FALSE)="","",VLOOKUP($A16,Sheet1!$A$3:$AW$699,2,FALSE)) -> PM.031
... A69: 696 | B69: =IF(VLOOKUP($A69,Sheet1!$A$3:$AW$699,20,FALSE)="","",VLOOKUP($A69,Sheet1!$A$3:$AW$699,20,FALSE)) -> MotorOverloadDerateHz | C69: =IF(VLOOKUP($A69,Sheet1!$A$3:$AW$699,25,FALSE)="","",VLOOKUP($A69,Sheet1!$A$3:$AW$699,25,FALSE)) -> All | D69: =IF(VLOOKUP($A69,Sheet1!$A$3:$AW$699,15,FALSE)="","",VLOOKUP($A69,Sheet1!$A$3:$AW$699,15,FALSE)) -> 0 | E69: =IF(VLOOKUP($A69,Sheet1!$A$3:$AW$699,16,FALSE)="","",VLOOKUP($A69,Sheet1!$A$3:$AW$699,16,FALSE)) -> 4096 | F69: =IF(VLOOKUP($A69,Sheet1!$A$3:$AW$699,17,FALSE)="","",VLOOKUP($A69,Sheet1!$A$3:$AW$699,17,FALSE)) -> 20 | G69: =IF(VLOOKUP($A69,Sheet1!$A$3:$AW$699,18,FALSE)="","",VLOOKUP($A69,Sheet1!$A$3:$AW$699,18,FALSE)) | H69: =IF(VLOOKUP($A69,Sheet1!$A$3:$AW$699,19,FALSE)="","",VLOOKUP($A69,Sheet1!$A$3:$AW$699,19,FALSE)) -> Hz | I69: =IF(VLOOKUP($A69,Sheet1!$A$3:$AW$699,5,FALSE)="","",VLOOKUP($A69,Sheet1!$A$3:$AW$699,5,FALSE)) -> INT | J69: Motor Overload Derate Hz | K69: 1-Motor | L69: =IF(VLOOKUP($A69,Sheet1!$A$3:$AW$699,7,FALSE)="★","x","") | M69: =IF(VLOOKUP($A69,Sheet1!$A$3:$AW$699,8,FALSE)="▲","x","") -> x | N69: =IF(VLOOKUP($A69,Sheet1!$A$3:$AW$699,9,FALSE)="●","x","") | O69: =IF(VLOOKUP($A69,Sheet1!$A$3:$AW$699,10,FALSE)="■","x","") | P69: =IF(VLOOKUP($A69,Sheet1!$A$3:$AW$699,2,FALSE)="","",VLOOKUP($A69,Sheet1!$A$3:$AW$699,2,FALSE)) -> PN.053

Sheet 2 - Drive
A1: Kinetix 5100 Servo Drive Parameters For more information see:
A2: Kinetix 5100 Servo Drive User Manual, publication 2198-UM004
A4: ID | B4: Name | C4: Control Mode | D4: Min. | E4: Max. | F4: Default Value | G4: Precision | H4: Units | I4: Data Type | J4: Comments | K4: Groups | L4: Read-only | M4: Set When Servo Off | N4: Valid After Power Cycle | O4: Volatile Parameter | P4: Parameter Number
A5: 14 | B5: =IF(VLOOKUP($A5,Sheet1!$A$3:$AW$699,20,FALSE)="","",VLOOKUP($A5,Sheet1!$A$3:$AW$699,20,FALSE)) -> DataType | C5: =IF(VLOOKUP($A5,Sheet1!$A$3:$AW$699,25,FALSE)="","",VLOOKUP($A5,Sheet1!$A$3:$AW$699,25,FALSE)) -> All | D5: =IF(VLOOKUP($A5,Sheet1!$A$3:$AW$699,15,FALSE)="","",VLOOKUP($A5,Sheet1!$A$3:$AW$699,15,FALSE)) -> 0 | E5: =IF(VLOOKUP($A5,Sheet1!$A$3:$AW$699,16,FALSE)="","",VLOOKUP($A5,Sheet1!$A$3:$AW$699,16,FALSE)) -> 1 | F5: =IF(VLOOKUP($A5,Sheet1!$A$3:$AW$699,17,FALSE)="","",VLOOKUP($A5,Sheet1!$A$3:$AW$699,17,FALSE)) -> 0 | G5: =IF(VLOOKUP($A5,Sheet1!$A$3:$AW$699,18,FALSE)="","",VLOOKUP($A5,Sheet1!$A$3:$AW$699,18,FALSE)) | H5: =IF(VLOOKUP($A5,Sheet1!$A$3:$AW$699,19,FALSE)="","",VLOOKUP($A5,Sheet1!$A$3:$AW$699,19,FALSE)) | I5: =IF(VLOOKUP($A5,Sheet1!$A$3:$AW$699,5,FALSE)="","",VLOOKUP($A5,Sheet1!$A$3:$AW$699,5,FALSE)) -> USINT | J5: Data Type Determines the data type of position, speed, acceleration reference, feedback and all related values. 0 = DINT | K5: 2-Drive | L5: =IF(VLOOKUP($A5,Sheet1!$A$3:$AW$699,7,FALSE)="★","x","") -> x | M5: =IF(VLOOKUP($A5,Sheet1!$A$3:$AW$699,8,FALSE)="▲","x","") | N5: =IF(VLOOKUP($A5,Sheet1!$A$3:$AW$699,9,FALSE)="●","x","") | O5: =IF(VLOOKUP($A5,Sheet1!$A$3:$AW$699,10,FALSE)="■","x","") | P5: =IF(VLOOKUP($A5,Sheet1!$A$3:$AW$699,2,FALSE)="","",VLOOKUP($A5,Sheet1!$A$3:$AW$699,2,FALSE))
A6: 15 | B6: =IF(VLOOKUP($A6,Sheet1!$A$3:$AW$699,20,FALSE)="","",VLOOKUP($A6,Sheet1!$A$3:$AW$699,20,FALSE)) -> PositionDataUnit | C6: =IF(VLOOKUP($A6,Sheet1!$A$3:$AW$699,25,FALSE)="","",VLOOKUP($A6,Sheet1!$A$3:$AW$699,25,FALSE)) -> All | D6: =IF(VLOOKUP($A6,Sheet1!$A$3:$AW$699,15,FALSE)="","",VLOOKUP($A6,Sheet1!$A$3:$AW$699,15,FALSE)) -> 0 | E6: =IF(VLOOKUP($A6,Sheet1!$A$3:$AW$699,16,FALSE)="","",VLOOKUP($A6,Sheet1!$A$3:$AW$699,16,FALSE)) -> 0 | F6: =IF(VLOOKUP($A6,Sheet1!$A$3:$AW$699,17,FALSE)="","",VLOOKUP($A6,Sheet1!$A$3:$AW$699,17,FALSE)) -> 0 | G6: =IF(VLOOKUP($A6,Sheet1!$A$3:$AW$699,18,FALSE)="","",VLOOKUP($A6,Sheet1!$A$3:$AW$699,18,FALSE)) | H6: =IF(VLOOKUP($A6,Sheet1!$A$3:$AW$699,19,FALSE)="","",VLOOKUP($A6,Sheet1!$A$3:$AW$699,19,FALSE)) | I6: =IF(VLOOKUP($A6,Sheet1!$A$3:$AW$699,5,FALSE)="","",VLOOKUP($A6,Sheet1!$A$3:$AW$699,5,FALSE)) -> USINT | J6: Position Data Unit Determines the data unit of position reference and feedback and all related attributes. 0 = PUU | K6: 2-Drive | L6: =IF(VLOOKUP($A6,Sheet1!$A$3:$AW$699,7,FALSE)="★","x","") -> x | M6: =IF(VLOOKUP($A6,Sheet1!$A$3:$AW$699,8,FALSE)="▲","x","") | N6: =IF(VLOOKUP($A6,Sheet1!$A$3:$AW$699,9,FALSE)="●","x","") | O6: =IF(VLOOKUP($A6,Sheet1!$A$3:$AW$699,10,FALSE)="■","x","") | P6: =IF(VLOOKUP($A6,Sheet1!$A$3:$AW$699,2,FALSE)="","",VLOOKUP($A6,Sheet1!$A$3:$AW$699,2,FALSE))
A7: 16 | B7: =IF(VLOOKUP($A7,Sheet1!$A$3:$AW$699,20,FALSE)="","",VLOOKUP($A7,Sheet1!$A$3:$AW$699,20,FALSE)) -> SpeedDataUnit | C7: =IF(VLOOKUP($A7,Sheet1!$A$3:$AW$699,25,FALSE)="","",VLOOKUP($A7,Sheet1!$A$3:$AW$699,25,FALSE)) -> All | D7: =IF(VLOOKUP($A7,Sheet1!$A$3:$AW$699,15,FALSE)="","",VLOOKUP($A7,Sheet1!$A$3:$AW$699,15,FALSE)) -> 0 | E7: =IF(VLOOKUP($A7,Sheet1!$A$3:$AW$699,16,FALSE)="","",VLOOKUP($A7,Sheet1!$A$3:$AW$699,16,FALSE)) -> 6 | F7: =IF(VLOOKUP($A7,Sheet1!$A$3:$AW$699,17,FALSE)="","",VLOOKUP($A7,Sheet1!$A$3:$AW$699,17,FALSE)) -> 1 | G7: =IF(VLOOKUP($A7,Sheet1!$A$3:$AW$699,18,FALSE)="","",VLOOKUP($A7,Sheet1!$A$3:$AW$699,18,FALSE)) | H7: =IF(VLOOKUP($A7,Sheet1!$A$3:$AW$699,19,FALSE)="","",VLOOKUP($A7,Sheet1!$A$3:$AW$699,19,FALSE)) | I7: =IF(VLOOKUP($A7,Sheet1!$A$3:$AW$699,5,FALSE)="","",VLOOKUP($A7,Sheet1!$A$3:$AW$699,5,FALSE)) -> USINT | J7: Speed Data Unit Determines the data unit of speed reference and feedback and all related attributes. 1 = 0.1RPM | K7: 2-Drive | L7: =IF(VLOOKUP($A7,Sheet1!$A$3:$AW$699,7,FALSE)="★","x","") -> x | M7: =IF(VLOOKUP($A7,Sheet1!$A$3:$AW$699,8,FALSE)="▲","x","") | N7: =IF(VLOOKUP($A7,Sheet1!$A$3:$AW$699,9,FALSE)="●","x","") | O7: =IF(VLOOKUP($A7,Sheet1!$A$3:$AW$699,10,FALSE)="■","x","") | P7: =IF(VLOOKUP($A7,Sheet1!$A$3:$AW$699,2,FALSE)="","",VLOOKUP($A7,Sheet1!$A$3:$AW$699,2,FALSE))
A8: 17 | B8: =IF(VLOOKUP($A8,Sheet1!$A$3:$AW$699,20,FALSE)="","",VLOOKUP($A8,Sheet1!$A$3:$AW$699,20,FALSE)) -> AccelDataUnit | C8: =IF(VLOOKUP($A8,Sheet1!$A$3:$AW$699,25,FALSE)="","",VLOOKUP($A8,Sheet1!$A$3:$AW$699,25,FALSE)) -> All | D8: =IF(VLOOKUP($A8,Sheet1!$A$3:$AW$699,15,FALSE)="","",VLOOKUP($A8,Sheet1!$A$3:$AW$699,15,FALSE)) -> 0 | E8: =IF(VLOOKUP($A8,Sheet1!$A$3:$AW$699,16,FALSE)="","",VLOOKUP($A8,Sheet1!$A$3:$AW$699,16,FALSE)) -> 6 | F8: =IF(VLOOKUP($A8,Sheet1!$A$3:$AW$699,17,FALSE)="","",VLOOKUP($A8,Sheet1!$A$3:$AW$699,17,FALSE)) -> 1 | G8: =IF(VLOOKUP($A8,Sheet1!$A$3:$AW$699,18,FALSE)="","",VLOOKUP($A8,Sheet1!$A$3:$AW$699,18,FALSE)) | H8: =IF(VLOOKUP($A8,Sheet1!$A$3:$AW$699,19,FALSE)="","",VLOOKUP($A8,Sheet1!$A$3:$AW$699,19,FALSE)) | I8: =IF(VLOOKUP($A8,Sheet1!$A$3:$AW$699,5,FALSE)="","",VLOOKUP($A8,Sheet1!$A$3:$AW$699,5,FALSE)) -> USINT | J8: Acceleration Data Unit Determines the data unit of acceleration (deceleration) reference and feedback and all related attributes. 1 = 0.1RPM/s | K8: 2-Drive | L8: =IF(VLOOKUP($A8,Sheet1!$A$3:$AW$699,7,FALSE)="★","x","") -> x | M8: =IF(VLOOKUP($A8,Sheet1!$A$3:$AW$699,8,FALSE)="▲","x","") | N8: =IF(VLOOKUP($A8,Sheet1!$A$3:$AW$699,9,FALSE)="●","x","") | O8: =IF(VLOOKUP($A8,Sheet1!$A$3:$AW$699,10,FALSE)="■","x","") | P8: =IF(VLOOKUP($A8,Sheet1!$A$3:$AW$699,2,FALSE)="","",VLOOKUP($A8,Sheet1!$A$3:$AW$699,2,FALSE))
A9: 18 | B9: =IF(VLOOKUP($A9,Sheet1!$A$3:$AW$699,20,FALSE)="","",VLOOKUP($A9,Sheet1!$A$3:$AW$699,20,FALSE)) -> TorqueDataUnit | C9: =IF(VLOOKUP($A9,Sheet1!$A$3:$AW$699,25,FALSE)="","",VLOOKUP($A9,Sheet1!$A$3:$AW$699,25,FALSE)) -> All | D9: =IF(VLOOKUP($A9,Sheet1!$A$3:$AW$699,15,FALSE)="","",VLOOKUP($A9,Sheet1!$A$3:$AW$699,15,FALSE)) -> 0 | E9: =IF(VLOOKUP($A9,Sheet1!$A$3:$AW$699,16,FALSE)="","",VLOOKUP($A9,Sheet1!$A$3:$AW$699,16,FALSE)) -> 1 | F9: =IF(VLOOKUP($A9,Sheet1!$A$3:$AW$699,17,FALSE)="","",VLOOKUP($A9,Sheet1!$A$3:$AW$699,17,FALSE)) -> 1 | G9: =IF(VLOOKUP($A9,Sheet1!$A$3:$AW$699,18,FALSE)="","",VLOOKUP($A9,Sheet1!$A$3:$AW$699,18,FALSE)) | H9: =IF(VLOOKUP($A9,Sheet1!$A$3:$AW$699,19,FALSE)="","",VLOOKUP($A9,Sheet1!$A$3:$AW$699,19,FALSE)) | I9: =IF(VLOOKUP($A9,Sheet1!$A$3:$AW$699,5,FALSE)="","",VLOOKUP($A9,Sheet1!$A$3:$AW$699,5,FALSE)) -> USINT | J9: Torque Data Unit Determines the data unit of torque reference and feedback and all related attributes. 1 = 0.1% | K9: 2-Drive | L9: =IF(VLOOKUP($A9,Sheet1!$A$3:$AW$699,7,FALSE)="★","x","") -> x | M9: =IF(VLOOKUP($A9,Sheet1!$A$3:$AW$699,8,FALSE)="▲","x","") | N9: =IF(VLOOKUP($A9,Sheet1!$A$3:$AW$699,9,FALSE)="●","x","") | O9: =IF(VLOOKUP($A9,Sheet1!$A$3:$AW$699,10,FALSE)="■","x","") | P9: =IF(VLOOKUP($A9,Sheet1!$A$3:$AW$699,2,FALSE)="","",VLOOKUP($A9,Sheet1!$A$3:$AW$699,2,FALSE))
A10: 19 | B10: =IF(VLOOKUP($A10,Sheet1!$A$3:$AW$699,20,FALSE)="","",VLOOKUP($A10,Sheet1!$A$3:$AW$699,20,FALSE)) -> TorqueRampTimeUnit | C10: =IF(VLOOKUP($A10,Sheet1!$A$3:$AW$699,25,FALSE)="","",VLOOKUP($A10,Sheet1!$A$3:$AW$699,25,FALSE)) -> All | D10: =IF(VLOOKUP($A10,Sheet1!$A$3:$AW$699,15,FALSE)="","",VLOOKUP($A10,Sheet1!$A$3:$AW$699,15,FALSE)) -> 0 | E10: =IF(VLOOKUP($A10,Sheet1!$A$3:$AW$699,16,FALSE)="","",VLOOKUP($A10,Sheet1!$A$3:$AW$699,16,FALSE)) -> 1 | F10: =IF(VLOOKUP($A10,Sheet1!$A$3:$AW$699,17,FALSE)="","",VLOOKUP($A10,Sheet1!$A$3:$AW$699,17,FALSE)) -> 0 | G10: =IF(VLOOKUP($A10,Sheet1!$A$3:$AW$699,18,FALSE)="","",VLOOKUP($A10,Sheet1!$A$3:$AW$699,18,FALSE)) | H10: =IF(VLOOKUP($A10,Sheet1!$A$3:$AW$699,19,FALSE)="","",VLOOKUP($A10,Sheet1!$A$3:$AW$699,19,FALSE)) | I10: =IF(VLOOKUP($A10,Sheet1!$A$3:$AW$699,5,FALSE)="","",VLOOKUP($A10,Sheet1!$A$3:$AW$699,5,FALSE)) -> USINT | J10: Torque Ramp Time Unit Determines the data unit of torque slope. 0 = millisecond | K10: 2-Drive | L10: =IF(VLOOKUP($A10,Sheet1!$A$3:$AW$699,7,FALSE)="★","x","") -> x | M10: =IF(VLOOKUP($A10,Sheet1!$A$3:$AW$699,8,FALSE)="▲","x","") | N10: =IF(VLOOKUP($A10,Sheet1!$A$3:$AW$699,9,FALSE)="●","x","") | O10: =IF(VLOOKUP($A10,Sheet1!$A$3:$AW$699,10,FALSE)="■","x","") | P10: =IF(VLOOKUP($A10,Sheet1!$A$3:$AW$699,2,FALSE)="","",VLOOKUP($A10,Sheet1!$A$3:$AW$699,2,FALSE))
A11: 20 | B11: =IF(VLOOKUP($A11,Sheet1!$A$3:$AW$699,20,FALSE)="","",VLOOKUP($A11,Sheet1!$A$3:$AW$699,20,FALSE)) -> OperatingMode | C11: =IF(VLOOKUP($A11,Sheet1!$A$3:$AW$699,25,FALSE)="","",VLOOKUP($A11,Sheet1!$A$3:$AW$699,25,FALSE)) -> IO | D11: =IF(VLOOKUP($A11,Sheet1!$A$3:$AW$699,15,FALSE)="","",VLOOKUP($A11,Sheet1!$A$3:$AW$699,15,FALSE)) -> 0 | E11: =IF(VLOOKUP($A11,Sheet1!$A$3:$AW$699,16,FALSE)="","",VLOOKUP($A11,Sheet1!$A$3:$AW$699,16,FALSE)) -> 6 | F11: =IF(VLOOKUP($A11,Sheet1!$A$3:$AW$699,17,FALSE)="","",VLOOKUP($A11,Sheet1!$A$3:$AW$699,17,FALSE)) -> 0 | G11: =IF(VLOOKUP($A11,Sheet1!$A$3:$AW$699,18,FALSE)="","",VLOOKUP($A11,Sheet1!$A$3:$AW$699,18,FALSE)) | H11: =IF(VLOOKUP($A11,Sheet1!$A$3:$AW$699,19,FALSE)="","",VLOOKUP($A11,Sheet1!$A$3:$AW$699,19,FALSE)) | I11: =IF(VLOOKUP($A11,Sheet1!$A$3:$AW$699,5,FALSE)="","",VLOOKUP($A11,Sheet1!$A$3:$AW$699,5,FALSE)) -> SINT | J11: Operating Mode Determines the drive operating mode when ID25 (Start Motion) has a zero-to-one transition. 0 = Mode not specified 1 = Position mode 2 = Speed mode 3 = Home mode 4 = Torque mode 5 = Gear mode 6 = Index mode | K11: 2-Drive | L11: =IF(VLOOKUP($A11,Sheet1!$A$3:$AW$699,7,FALSE)="★","x","") | M11: =IF(VLOOKUP($A11,Sheet1!$A$3:$AW$699,8,FALSE)="▲","x","") | N11: =IF(VLOOKUP($A11,Sheet1!$A$3:$AW$699,9,FALSE)="●","x","") | O11: =IF(VLOOKUP($A11,Sheet1!$A$3:$AW$699,10,FALSE)="■","x","") | P11: =IF(VLOOKUP($A11,Sheet1!$A$3:$AW$699,2,FALSE)="","",VLOOKUP($A11,Sheet1!$A$3:$AW$699,2,FALSE))
A12: 21 | B12: =IF(VLOOKUP($A12,Sheet1!$A$3:$AW$699,20,FALSE)="","",VLOOKUP($A12,Sheet1!$A$3:$AW$699,20,FALSE)) -> ServoOn | C12: =IF(VLOOKUP($A12,Sheet1!$A$3:$AW$699,25,FALSE)="","",VLOOKUP($A12,Sheet1!$A$3:$AW$699,25,FALSE)) -> IO | D12: =IF(VLOOKUP($A12,Sheet1!$A$3:$AW$699,15,FALSE)="","",VLOOKUP($A12,Sheet1!$A$3:$AW$699,15,FALSE)) -> 0 | E12: =IF(VLOOKUP($A12,Sheet1!$A$3:$AW$699,16,FALSE)="","",VLOOKUP($A12,Sheet1!$A$3:$AW$699,16,FALSE)) -> 1 | F12: =IF(VLOOKUP($A12,Sheet1!$A$3:$AW$699,17,FALSE)="","",VLOOKUP($A12,Sheet1!$A$3:$AW$699,17,FALSE)) -> 0 | G12: =IF(VLOOKUP($A12,Sheet1!$A$3:$AW$699,18,FALSE)="","",VLOOKUP($A12,Sheet1!$A$3:$AW$699,18,FALSE)) | H12: =IF(VLOOKUP($A12,Sheet1!$A$3:$AW$699,19,FALSE)="","",VLOOKUP($A12,Sheet1!$A$3:$AW$699,19,FALSE)) | I12: =IF(VLOOKUP($A12,Sheet1!$A$3:$AW$699,5,FALSE)="","",VLOOKUP($A12,Sheet1!$A$3:$AW$699,5,FALSE)) -> BOOL | J12: Servo On A zero-to-one transition will activate the drive. | K12: 2-Drive | L12: =IF(VLOOKUP($A12,Sheet1!$A$3:$AW$699,7,FALSE)="★","x","") | M12: =IF(VLOOKUP($A12,Sheet1!$A$3:$AW$699,8,FALSE)="▲","x","") | N12: =IF(VLOOKUP($A12,Sheet1!$A$3:$AW$699,9,FALSE)="●","x","") | O12: =IF(VLOOKUP($A12,Sheet1!$A$3:$AW$699,10,FALSE)="■","x","") | P12: =IF(VLOOKUP($A12,Sheet1!$A$3:$AW$699,2,FALSE)="","",VLOOKUP($A12,Sheet1!$A$3:$AW$699,2,FALSE))
A13: 22 | B13: =IF(VLOOKUP($A13,Sheet1!$A$3:$AW$699,20,FALSE)="","",VLOOKUP($A13,Sheet1!$A$3:$AW$699,20,FALSE)) -> ServoOff | C13: =IF(VLOOKUP($A13,Sheet1!$A$3:$AW$699,25,FALSE)="","",VLOOKUP($A13,Sheet1!$A$3:$AW$699,25,FALSE)) -> IO | D13: =IF(VLOOKUP($A13,Sheet1!$A$3:$AW$699,15,FALSE)="","",VLOOKUP($A13,Sheet1!$A$3:$AW$699,15,FALSE)) -> 0 | E13: =IF(VLOOKUP($A13,Sheet1!$A$3:$AW$699,16,FALSE)="","",VLOOKUP($A13,Sheet1!$A$3:$AW$699,16,FALSE)) -> 1 | F13: =IF(VLOOKUP($A13,Sheet1!$A$3:$AW$699,17,FALSE)="","",VLOOKUP($A13,Sheet1!$A$3:$AW$699,17,FALSE)) -> 0 | G13: =IF(VLOOKUP($A13,Sheet1!$A$3:$AW$699,18,FALSE)="","",VLOOKUP($A13,Sheet1!$A$3:$AW$699,18,FALSE)) | H13: =IF(VLOOKUP($A13,Sheet1!$A$3:$AW$699,19,FALSE)="","",VLOOKUP($A13,Sheet1!$A$3:$AW$699,19,FALSE)) | I13: =IF(VLOOKUP($A13,Sheet1!$A$3:$AW$699,5,FALSE)="","",VLOOKUP($A13,Sheet1!$A$3:$AW$699,5,FALSE)) -> BOOL | J13: Servo Off A zero-to-one transition will de-activate the drive. | K13: 2-Drive | L13: =IF(VLOOKUP($A13,Sheet1!$A$3:$AW$699,7,FALSE)="★","x","") | M13: =IF(VLOOKUP($A13,Sheet1!$A$3:$AW$699,8,FALSE)="▲","x","") | N13: =IF(VLOOKUP($A13,Sheet1!$A$3:$AW$699,9,FALSE)="●","x","") | O13: =IF(VLOOKUP($A13,Sheet1!$A$3:$AW$699,10,FALSE)="■","x","") | P13: =IF(VLOOKUP($A13,Sheet1!$A$3:$AW$699,2,FALSE)="","",VLOOKUP($A13,Sheet1!$A$3:$AW$699,2,FALSE))
A14: 23 | B14: =IF(VLOOKUP($A14,Sheet1!$A$3:$AW$699,20,FALSE)="","",VLOOKUP($A14,Sheet1!$A$3:$AW$699,20,FALSE)) -> StopMotion | C14: =IF(VLOOKUP($A14,Sheet1!$A$3:$AW$699,25,FALSE)="","",VLOOKUP($A14,Sheet1!$A$3:$AW$699,25,FALSE)) -> IO | D14: =IF(VLOOKUP($A14,Sheet1!$A$3:$AW$699,15,FALSE)="","",VLOOKUP($A14,Sheet1!$A$3:$AW$699,15,FALSE)) -> 0 | E14: =IF(VLOOKUP($A14,Sheet1!$A$3:$AW$699,16,FALSE)="","",VLOOKUP($A14,Sheet1!$A$3:$AW$699,16,FALSE)) -> 1 | F14: =IF(VLOOKUP($A14,Sheet1!$A$3:$AW$699,17,FALSE)="","",VLOOKUP($A14,Sheet1!$A$3:$AW$699,17,FALSE)) -> 0 | G14: =IF(VLOOKUP($A14,Sheet1!$A$3:$AW$699,18,FALSE)="","",VLOOKUP($A14,Sheet1!$A$3:$AW$699,18,FALSE)) | H14: =IF(VLOOKUP($A14,Sheet1!$A$3:$AW$699,19,FALSE)="","",VLOOKUP($A14,Sheet1!$A$3:$AW$699,19,FALSE)) | I14: =IF(VLOOKUP($A14,Sheet1!$A$3:$AW$699,5,FALSE)="","",VLOOKUP($A14,Sheet1!$A$3:$AW$699,5,FALSE)) -> BOOL | J14: Stop Motion A zero-to-one transition will stop the drive. | K14: 2-Drive | L14: =IF(VLOOKUP($A14,Sheet1!$A$3:$AW$699,7,FALSE)="★","x","") | M14: =IF(VLOOKUP($A14,Sheet1!$A$3:$AW$699,8,FALSE)="▲","x","") | N14: =IF(VLOOKUP($A14,Sheet1!$A$3:$AW$699,9,FALSE)="●","x","") | O14: =IF(VLOOKUP($A14,Sheet1!$A$3:$AW$699,10,FALSE)="■","x","") | P14: =IF(VLOOKUP($A14,Sheet1!$A$3:$AW$699,2,FALSE)="","",VLOOKUP($A14,Sheet1!$A$3:$AW$699,2,FALSE))
A15: 24 | B15: =IF(VLOOKUP($A15,Sheet1!$A$3:$AW$699,20,FALSE)="","",VLOOKUP($A15,Sheet1!$A$3:$AW$699,20,FALSE)) -> FaultReset | C15: =IF(VLOOKUP($A15,Sheet1!$A$3:$AW$699,25,FALSE)="","",VLOOKUP($A15,Sheet1!$A$3:$AW$699,25,FALSE)) -> IO | D15: =IF(VLOOKUP($A15,Sheet1!$A$3:$AW$699,15,FALSE)="","",VLOOKUP($A15,Sheet1!$A$3:$AW$699,15,FALSE)) -> 0 | E15: =IF(VLOOKUP($A15,Sheet1!$A$3:$AW$699,16,FALSE)="","",VLOOKUP($A15,Sheet1!$A$3:$AW$699,16,FALSE)) -> 1 | F15: =IF(VLOOKUP($A15,Sheet1!$A$3:$AW$699,17,FALSE)="","",VLOOKUP($A15,Sheet1!$A$3:$AW$699,17,FALSE)) -> 0 | G15: =IF(VLOOKUP($A15,Sheet1!$A$3:$AW$699,18,FALSE)="","",VLOOKUP($A15,Sheet1!$A$3:$AW$699,18,FALSE)) | H15: =IF(VLOOKUP($A15,Sheet1!$A$3:$AW$699,19,FALSE)="","",VLOOKUP($A15,Sheet1!$A$3:$AW$699,19,FALSE)) | I15: =IF(VLOOKUP($A15,Sheet1!$A$3:$AW$699,5,FALSE)="","",VLOOKUP($A15,Sheet1!$A$3:$AW$699,5,FALSE)) -> BOOL | J15: Fault Reset A zero-to-one transition will try to clear a fault on the drive. | K15: 2-Drive | L15: =IF(VLOOKUP($A15,Sheet1!$A$3:$AW$699,7,FALSE)="★","x","") | M15: =IF(VLOOKUP($A15,Sheet1!$A$3:$AW$699,8,FALSE)="▲","x","") | N15: =IF(VLOOKUP($A15,Sheet1!$A$3:$AW$699,9,FALSE)="●","x","") | O15: =IF(VLOOKUP($A15,Sheet1!$A$3:$AW$699,10,FALSE)="■","x","") | P15: =IF(VLOOKUP($A15,Sheet1!$A$3:$AW$699,2,FALSE)="","",VLOOKUP($A15,Sheet1!$A$3:$AW$699,2,FALSE))
A16: 25 | B16: =IF(VLOOKUP($A16,Sheet1!$A$3:$AW$699,20,FALSE)="","",VLOOKUP($A16,Sheet1!$A$3:$AW$699,20,FALSE)) -> StartMotion | C16: =IF(VLOOKUP($A16,Sheet1!$A$3:$AW$699,25,FALSE)="","",VLOOKUP($A16,Sheet1!$A$3:$AW$699,25,FALSE)) -> IO | D16: =IF(VLOOKUP($A16,Sheet1!$A$3:$AW$699,15,FALSE)="","",VLOOKUP($A16,Sheet1!$A$3:$AW$699,15,FALSE)) -> 0 | E16: =IF(VLOOKUP($A16,Sheet1!$A$3:$AW$699,16,FALSE)="","",VLOOKUP($A16,Sheet1!$A$3:$AW$699,16,FALSE)) -> 1 | F16: =IF(VLOOKUP($A16,Sheet1!$A$3:$AW$699,17,FALSE)="","",VLOOKUP($A16,Sheet1!$A$3:$AW$699,17,FALSE)) -> 0 | G16: =IF(VLOOKUP($A16,Sheet1!$A$3:$AW$699,18,FALSE)="","",VLOOKUP($A16,Sheet1!$A$3:$AW$699,18,FALSE)) | H16: =IF(VLOOKUP($A16,Sheet1!$A$3:$AW$699,19,FALSE)="","",VLOOKUP($A16,Sheet1!$A$3:$AW$699,19,FALSE)) | I16: =IF(VLOOKUP($A16,Sheet1!$A$3:$AW$699,5,FALSE)="","",VLOOKUP($A16,Sheet1!$A$3:$AW$699,5,FALSE)) -> BOOL | J16: Start Motion A zero-to-one transition means the motion command has been issued from the external controller. | K16: 2-Drive | L16: =IF(VLOOKUP($A16,Sheet1!$A$3:$AW$699,7,FALSE)="★","x","") | M16: =IF(VLOOKUP($A16,Sheet1!$A$3:$AW$699,8,FALSE)="▲","x","") | N16: =IF(VLOOKUP($A16,Sheet1!$A$3:$AW$699,9,FALSE)="●","x","") | O16: =IF(VLOOKUP($A16,Sheet1!$A$3:$AW$699,10,FALSE)="■","x","") | P16: =IF(VLOOKUP($A16,Sheet1!$A$3:$AW$699,2,FALSE)="","",VLOOKUP($A16,Sheet1!$A$3:$AW$699,2,FALSE))
... A61: 81 | B61: =IF(VLOOKUP($A61,Sheet1!$A$3:$AW$699,20,FALSE)="","",VLOOKUP($A61,Sheet1!$A$3:$AW$699,20,FALSE)) -> CamMasterLockPosition | C61: =IF(VLOOKUP($A61,Sheet1!$A$3:$AW$699,25,FALSE)="","",VLOOKUP($A61,Sheet1!$A$3:$AW$699,25,FALSE)) -> IO | D61: =IF(VLOOKUP($A61,Sheet1!$A$3:$AW$699,15,FALSE)="","",VLOOKUP($A61,Sheet1!$A$3:$AW$699,15,FALSE)) -> -1073741824 | E61: =IF(VLOOKUP($A61,Sheet1!$A$3:$AW$699,16,FALSE)="","",VLOOKUP($A61,Sheet1!$A$3:$AW$699,16,FALSE)) -> 1073741823 | F61: =IF(VLOOKUP($A61,Sheet1!$A$3:$AW$699,17,FALSE)="","",VLOOKUP($A61,Sheet1!$A$3:$AW$699,17,FALSE)) -> 0 | G61: =IF(VLOOKUP($A61,Sheet1!$A$3:$AW$699,18,FALSE)="","",VLOOKUP($A61,Sheet1!$A$3:$AW$699,18,FALSE)) | H61: =IF(VLOOKUP($A61,Sheet1!$A$3:$AW$699,19,FALSE)="","",VLOOKUP($A61,Sheet1!$A$3:$AW$699,19,FALSE)) | I61: =IF(VLOOKUP($A61,Sheet1!$A$3:$AW$699,5,FALSE)="","",VLOOKUP($A61,Sheet1!$A$3:$AW$699,5,FALSE)) -> DINT | J61: This determines the master location where the slave axis locks to the mater axis. Valid only when CamExecutionSchedule = 2, 3, 4 | K61: 2-Drive | L61: =IF(VLOOKUP($A61,Sheet1!$A$3:$AW$699,7,FALSE)="★","x","") | M61: =IF(VLOOKUP($A61,Sheet1!$A$3:$AW$699,8,FALSE)="▲","x","") | N61: =IF(VLOOKUP($A61,Sheet1!$A$3:$AW$699,9,FALSE)="●","x","") | O61: =IF(VLOOKUP($A61,Sheet1!$A$3:$AW$699,10,FALSE)="■","x","") | P61: =IF(VLOOKUP($A61,Sheet1!$A$3:$AW$699,2,FALSE)="","",VLOOKUP($A61,Sheet1!$A$3:$AW$699,2,FALSE))
A62: 98 | B62: =IF(VLOOKUP($A62,Sheet1!$A$3:$AW$699,20,FALSE)="","",VLOOKUP($A62,Sheet1!$A$3:$AW$699,20,FALSE)) -> DriveConnectionStatus | C62: =IF(VLOOKUP($A62,Sheet1!$A$3:$AW$699,25,FALSE)="","",VLOOKUP($A62,Sheet1!$A$3:$AW$699,25,FALSE)) | D62: =IF(VLOOKUP($A62,Sheet1!$A$3:$AW$699,15,FALSE)="","",VLOOKUP($A62,Sheet1!$A$3:$AW$699,15,FALSE)) -> 0x00000000 | E62: =IF(VLOOKUP($A62,Sheet1!$A$3:$AW$699,16,FALSE)="","",VLOOKUP($A62,Sheet1!$A$3:$AW$699,16,FALSE)) -> 0xFFFFFFFF | F62: =IF(VLOOKUP($A62,Sheet1!$A$3:$AW$699,17,FALSE)="","",VLOOKUP($A62,Sheet1!$A$3:$AW$699,17,FALSE)) -> 0x00000000 | G62: =IF(VLOOKUP($A62,Sheet1!$A$3:$AW$699,18,FALSE)="","",VLOOKUP($A62,Sheet1!$A$3:$AW$699,18,FALSE)) | H62: =IF(VLOOKUP($A62,Sheet1!$A$3:$AW$699,19,FALSE)="","",VLOOKUP($A62,Sheet1!$A$3:$AW$699,19,FALSE)) | I62: =IF(VLOOKUP($A62,Sheet1!$A$3:$AW$699,5,FALSE)="","",VLOOKUP($A62,Sheet1!$A$3:$AW$699,5,FALSE)) -> UDINT | J62: Drive Connection Status | L62: =IF(VLOOKUP($A62,Sheet1!$A$3:$AW$699,7,FALSE)="★","x","") -> x | M62: =IF(VLOOKUP($A62,Sheet1!$A$3:$AW$699,8,FALSE)="▲","x","") | N62: =IF(VLOOKUP($A62,Sheet1!$A$3:$AW$699,9,FALSE)="●","x","") | O62: =IF(VLOOKUP($A62,Sheet1!$A$3:$AW$699,10,FALSE)="■","x","") | P62: =IF(VLOOKUP($A62,Sheet1!$A$3:$AW$699,2,FALSE)="","",VLOOKUP($A62,Sheet1!$A$3:$AW$699,2,FALSE))
A63: 99 | B63: =IF(VLOOKUP($A63,Sheet1!$A$3:$AW$699,20,FALSE)="","",VLOOKUP($A63,Sheet1!$A$3:$AW$699,20,FALSE)) -> DriveConfigurationSignature | C63: =IF(VLOOKUP($A63,Sheet1!$A$3:$AW$699,25,FALSE)="","",VLOOKUP($A63,Sheet1!$A$3:$AW$699,25,FALSE)) | D63: =IF(VLOOKUP($A63,Sheet1!$A$3:$AW$699,15,FALSE)="","",VLOOKUP($A63,Sheet1!$A$3:$AW$699,15,FALSE)) -> 0x00000000 | E63: =IF(VLOOKUP($A63,Sheet1!$A$3:$AW$699,16,FALSE)="","",VLOOKUP($A63,Sheet1!$A$3:$AW$699,16,FALSE)) -> 0xFFFFFFFF | F63: =IF(VLOOKUP($A63,Sheet1!$A$3:$AW$699,17,FALSE)="","",VLOOKUP($A63,Sheet1!$A$3:$AW$699,17,FALSE)) -> 0x00000000 | G63: =IF(VLOOKUP($A63,Sheet1!$A$3:$AW$699,18,FALSE)="","",VLOOKUP($A63,Sheet1!$A$3:$AW$699,18,FALSE)) | H63: =IF(VLOOKUP($A63,Sheet1!$A$3:$AW$699,19,FALSE)="","",VLOOKUP($A63,Sheet1!$A$3:$AW$699,19,FALSE)) | I63: =IF(VLOOKUP($A63,Sheet1!$A$3:$AW$699,5,FALSE)="","",VLOOKUP($A63,Sheet1!$A$3:$AW$699,5,FALSE)) -> UDINT | J63: Drive Configuration Signature | L63: =IF(VLOOKUP($A63,Sheet1!$A$3:$AW$699,7,FALSE)="★","x","") -> x | M63: =IF(VLOOKUP($A63,Sheet1!$A$3:$AW$699,8,FALSE)="▲","x","") | N63: =IF(VLOOKUP($A63,Sheet1!$A$3:$AW$699,9,FALSE)="●","x","") | O63: =IF(VLOOKUP($A63,Sheet1!$A$3:$AW$699,10,FALSE)="■","x","") | P63: =IF(VLOOKUP($A63,Sheet1!$A$3:$AW$699,2,FALSE)="","",VLOOKUP($A63,Sheet1!$A$3:$AW$699,2,FALSE))
A64: 651 | B64: =IF(VLOOKUP($A64,Sheet1!$A$3:$AW$699,20,FALSE)="","",VLOOKUP($A64,Sheet1!$A$3:$AW$699,20,FALSE)) -> HardwareRevision | C64: =IF(VLOOKUP($A64,Sheet1!$A$3:$AW$699,25,FALSE)="","",VLOOKUP($A64,Sheet1!$A$3:$AW$699,25,FALSE)) -> All | D64: =IF(VLOOKUP($A64,Sheet1!$A$3:$AW$699,15,FALSE)="","",VLOOKUP($A64,Sheet1!$A$3:$AW$699,15,FALSE)) -> 0 | E64: =IF(VLOOKUP($A64,Sheet1!$A$3:$AW$699,16,FALSE)="","",VLOOKUP($A64,Sheet1!$A$3:$AW$699,16,FALSE)) -> 0xFFFF | F64: =IF(VLOOKUP($A64,Sheet1!$A$3:$AW$699,17,FALSE)="","",VLOOKUP($A64,Sheet1!$A$3:$AW$699,17,FALSE)) -> 0 | G64: =IF(VLOOKUP($A64,Sheet1!$A$3:$AW$699,18,FALSE)="","",VLOOKUP($A64,Sheet1!$A$3:$AW$699,18,FALSE)) | H64: =IF(VLOOKUP($A64,Sheet1!$A$3:$AW$699,19,FALSE)="","",VLOOKUP($A64,Sheet1!$A$3:$AW$699,19,FALSE)) | I64: =IF(VLOOKUP($A64,Sheet1!$A$3:$AW$699,5,FALSE)="","",VLOOKUP($A64,Sheet1!$A$3:$AW$699,5,FALSE)) -> UINT | J64: Hardware Revision high byte = Major version low byte = Minor version | K64: 2-Drive | L64: =IF(VLOOKUP($A64,Sheet1!$A$3:$AW$699,7,FALSE)="★","x","") -> x | M64: =IF(VLOOKUP($A64,Sheet1!$A$3:$AW$699,8,FALSE)="▲","x","") | N64: =IF(VLOOKUP($A64,Sheet1!$A$3:$AW$699,9,FALSE)="●","x","") | O64: =IF(VLOOKUP($A64,Sheet1!$A$3:$AW$699,10,FALSE)="■","x","") -> x | P64: =IF(VLOOKUP($A64,Sheet1!$A$3:$AW$699,2,FALSE)="","",VLOOKUP($A64,Sheet1!$A$3:$AW$699,2,FALSE)) -> PN.027
A65: 652 | B65: =IF(VLOOKUP($A65,Sheet1!$A$3:$AW$699,20,FALSE)="","",VLOOKUP($A65,Sheet1!$A$3:$AW$699,20,FALSE)) -> DriveName | C65: =IF(VLOOKUP($A65,Sheet1!$A$3:$AW$699,25,FALSE)="","",VLOOKUP($A65,Sheet1!$A$3:$AW$699,25,FALSE)) -> All | D65: =IF(VLOOKUP($A65,Sheet1!$A$3:$AW$699,15,FALSE)="","",VLOOKUP($A65,Sheet1!$A$3:$AW$699,15,FALSE)) | E65: =IF(VLOOKUP($A65,Sheet1!$A$3:$AW$699,16,FALSE)="","",VLOOKUP($A65,Sheet1!$A$3:$AW$699,16,FALSE)) | F65: =IF(VLOOKUP($A65,Sheet1!$A$3:$AW$699,17,FALSE)="","",VLOOKUP($A65,Sheet1!$A$3:$AW$699,17,FALSE)) | G65: =IF(VLOOKUP($A65,Sheet1!$A$3:$AW$699,18,FALSE)="","",VLOOKUP($A65,Sheet1!$A$3:$AW$699,18,FALSE)) | H65: =IF(VLOOKUP($A65,Sheet1!$A$3:$AW$699,19,FALSE)="","",VLOOKUP($A65,Sheet1!$A$3:$AW$699,19,FALSE)) | I65: =IF(VLOOKUP($A65,Sheet1!$A$3:$AW$699,5,FALSE)="","",VLOOKUP($A65,Sheet1!$A$3:$AW$699,5,FALSE)) -> SHORT_STRING | J65: Drive Name [0]-[31] | K65: 2-Drive | L65: =IF(VLOOKUP($A65,Sheet1!$A$3:$AW$699,7,FALSE)="★","x","") | M65: =IF(VLOOKUP($A65,Sheet1!$A$3:$AW$699,8,FALSE)="▲","x","") -> x | N65: =IF(VLOOKUP($A65,Sheet1!$A$3:$AW$699,9,FALSE)="●","x","") | O65: =IF(VLOOKUP($A65,Sheet1!$A$3:$AW$699,10,FALSE)="■","x","") | P65: =IF(VLOOKUP($A65,Sheet1!$A$3:$AW$699,2,FALSE)="","",VLOOKUP($A65,Sheet1!$A$3:$AW$699,2,FALSE)) -> PN.028
A66: 653 | B66: =IF(VLOOKUP($A66,Sheet1!$A$3:$AW$699,20,FALSE)="","",VLOOKUP($A66,Sheet1!$A$3:$AW$699,20,FALSE)) -> DriveSerialNumber | C66: =IF(VLOOKUP($A66,Sheet1!$A$3:$AW$699,25,FALSE)="","",VLOOKUP($A66,Sheet1!$A$3:$AW$699,25,FALSE)) -> All | D66: =IF(VLOOKUP($A66,Sheet1!$A$3:$AW$699,15,FALSE)="","",VLOOKUP($A66,Sheet1!$A$3:$AW$699,15,FALSE)) -> 0 | E66: =IF(VLOOKUP($A66,Sheet1!$A$3:$AW$699,16,FALSE)="","",VLOOKUP($A66,Sheet1!$A$3:$AW$699,16,FALSE)) -> 0xFFFFFFFF | F66: =IF(VLOOKUP($A66,Sheet1!$A$3:$AW$699,17,FALSE)="","",VLOOKUP($A66,Sheet1!$A$3:$AW$699,17,FALSE)) -> 0 | G66: =IF(VLOOKUP($A66,Sheet1!$A$3:$AW$699,18,FALSE)="","",VLOOKUP($A66,Sheet1!$A$3:$AW$699,18,FALSE)) | H66: =IF(VLOOKUP($A66,Sheet1!$A$3:$AW$699,19,FALSE)="","",VLOOKUP($A66,Sheet1!$A$3:$AW$699,19,FALSE)) | I66: =IF(VLOOKUP($A66,Sheet1!$A$3:$AW$699,5,FALSE)="","",VLOOKUP($A66,Sheet1!$A$3:$AW$699,5,FALSE)) -> UDINT | J66: Drive Serial Number | K66: 2-Drive | L66: =IF(VLOOKUP($A66,Sheet1!$A$3:$AW$699,7,FALSE)="★","x","") -> x | M66: =IF(VLOOKUP($A66,Sheet1!$A$3:$AW$699,8,FALSE)="▲","x","") | N66: =IF(VLOOKUP($A66,Sheet1!$A$3:$AW$699,9,FALSE)="●","x","") | O66: =IF(VLOOKUP($A66,Sheet1!$A$3:$AW$699,10,FALSE)="■","x","") -> x | P66: =IF(VLOOKUP($A66,Sheet1!$A$3:$AW$699,2,FALSE)="","",VLOOKUP($A66,Sheet1!$A$3:$AW$699,2,FALSE)) -> PN.036
A67: 657 | B67: =IF(VLOOKUP($A67,Sheet1!$A$3:$AW$699,20,FALSE)="","",VLOOKUP($A67,Sheet1!$A$3:$AW$699,20,FALSE)) -> InverterTemperature | C67: =IF(VLOOKUP($A67,Sheet1!$A$3:$AW$699,25,FALSE)="","",VLOOKUP($A67,Sheet1!$A$3:$AW$699,25,FALSE)) -> All | D67: =IF(VLOOKUP($A67,Sheet1!$A$3:$AW$699,15,FALSE)="","",VLOOKUP($A67,Sheet1!$A$3:$AW$699,15,FALSE)) -> 0 | E67: =IF(VLOOKUP($A67,Sheet1!$A$3:$AW$699,16,FALSE)="","",VLOOKUP($A67,Sheet1!$A$3:$AW$699,16,FALSE)) -> 0xFFFFFFFF | F67: =IF(VLOOKUP($A67,Sheet1!$A$3:$AW$699,17,FALSE)="","",VLOOKUP($A67,Sheet1!$A$3:$AW$699,17,FALSE)) -> 0 | G67: =IF(VLOOKUP($A67,Sheet1!$A$3:$AW$699,18,FALSE)="","",VLOOKUP($A67,Sheet1!$A$3:$AW$699,18,FALSE)) | H67: =IF(VLOOKUP($A67,Sheet1!$A$3:$AW$699,19,FALSE)="","",VLOOKUP($A67,Sheet1!$A$3:$AW$699,19,FALSE)) -> oC | I67: =IF(VLOOKUP($A67,Sheet1!$A$3:$AW$699,5,FALSE)="","",VLOOKUP($A67,Sheet1!$A$3:$AW$699,5,FALSE)) -> UDINT | J67: Inverter Temperature | K67: 2-Drive | L67: =IF(VLOOKUP($A67,Sheet1!$A$3:$AW$699,7,FALSE)="★","x","") -> x | M67: =IF(VLOOKUP($A67,Sheet1!$A$3:$AW$699,8,FALSE)="▲","x","") | N67: =IF(VLOOKUP($A67,Sheet1!$A$3:$AW$699,9,FALSE)="●","x","") | O67: =IF(VLOOKUP($A67,Sheet1!$A$3:$AW$699,10,FALSE)="■","x","") -> x | P67: =IF(VLOOKUP($A67,Sheet1!$A$3:$AW$699,2,FALSE)="","",VLOOKUP($A67,Sheet1!$A$3:$AW$699,2,FALSE)) -> PN.039
A68: 662 | B68: =IF(VLOOKUP($A68,Sheet1!$A$3:$AW$699,20,FALSE)="","",VLOOKUP($A68,Sheet1!$A$3:$AW$699,20,FALSE)) -> ProductCode | C68: =IF(VLOOKUP($A68,Sheet1!$A$3:$AW$699,25,FALSE)="","",VLOOKUP($A68,Sheet1!$A$3:$AW$699,25,FALSE)) -> All | D68: =IF(VLOOKUP($A68,Sheet1!$A$3:$AW$699,15,FALSE)="","",VLOOKUP($A68,Sheet1!$A$3:$AW$699,15,FALSE)) -> 1 | E68: =IF(VLOOKUP($A68,Sheet1!$A$3:$AW$699,16,FALSE)="","",VLOOKUP($A68,Sheet1!$A$3:$AW$699,16,FALSE)) -> 65535 | F68: =IF(VLOOKUP($A68,Sheet1!$A$3:$AW$699,17,FALSE)="","",VLOOKUP($A68,Sheet1!$A$3:$AW$699,17,FALSE)) -> 1 | G68: =IF(VLOOKUP($A68,Sheet1!$A$3:$AW$699,18,FALSE)="","",VLOOKUP($A68,Sheet1!$A$3:$AW$699,18,FALSE)) | H68: =IF(VLOOKUP($A68,Sheet1!$A$3:$AW$699,19,FALSE)="","",VLOOKUP($A68,Sheet1!$A$3:$AW$699,19,FALSE)) | I68: =IF(VLOOKUP($A68,Sheet1!$A$3:$AW$699,5,FALSE)="","",VLOOKUP($A68,Sheet1!$A$3:$AW$699,5,FALSE)) -> UINT | J68: Product Code 1 = 2198-E1004-ERS 2 = 2198-E1007-ERS 3 = 2198-E1015-ERS 4 = 2198-E1020-ERS 5 = 2198-E2030-ERS 6 = 2198-E2055-ERS 7 = 2198-E2075-ERS 9 = 2198-E2150-ERS 10 = 2198-E4004-ERS 11 = 2198-E4007-ERS 12 = 2198-E4015-ERS 13 = 2198-E4020-ERS 14 = 2198-E4030-ERS 15 = 2198-E4055-ERS 16 = 2198-E4075-ERS 17 = 2198-E4150-ERS | K68: 2-Drive | L68: =IF(VLOOKUP($A68,Sheet1!$A$3:$AW$699,7,FALSE)="★","x","") -> x | M68: =IF(VLOOKUP($A68,Sheet1!$A$3:$AW$699,8,FALSE)="▲","x","") | N68: =IF(VLOOKUP($A68,Sheet1!$A$3:$AW$699,9,FALSE)="●","x","") | O68: =IF(VLOOKUP($A68,Sheet1!$A$3:$AW$699,10,FALSE)="■","x","") -> x | P68: =IF(VLOOKUP($A68,Sheet1!$A$3:$AW$699,2,FALSE)="","",VLOOKUP($A68,Sheet1!$A$3:$AW$699,2,FALSE)) -> PN.047
A69: 673 | B69: =IF(VLOOKUP($A69,Sheet1!$A$3:$AW$699,20,FALSE)="","",VLOOKUP($A69,Sheet1!$A$3:$AW$699,20,FALSE)) -> FwRevision | C69: =IF(VLOOKUP($A69,Sheet1!$A$3:$AW$699,25,FALSE)="","",VLOOKUP($A69,Sheet1!$A$3:$AW$699,25,FALSE)) -> All | D69: =IF(VLOOKUP($A69,Sheet1!$A$3:$AW$699,15,FALSE)="","",VLOOKUP($A69,Sheet1!$A$3:$AW$699,15,FALSE)) -> 0 | E69: =IF(VLOOKUP($A69,Sheet1!$A$3:$AW$699,16,FALSE)="","",VLOOKUP($A69,Sheet1!$A$3:$AW$699,16,FALSE)) -> 32767 | F69: =IF(VLOOKUP($A69,Sheet1!$A$3:$AW$699,17,FALSE)="","",VLOOKUP($A69,Sheet1!$A$3:$AW$699,17,FALSE)) -> 0 | G69: =IF(VLOOKUP($A69,Sheet1!$A$3:$AW$699,18,FALSE)="","",VLOOKUP($A69,Sheet1!$A$3:$AW$699,18,FALSE)) | H69: =IF(VLOOKUP($A69,Sheet1!$A$3:$AW$699,19,FALSE)="","",VLOOKUP($A69,Sheet1!$A$3:$AW$699,19,FALSE)) | I69: =IF(VLOOKUP($A69,Sheet1!$A$3:$AW$699,5,FALSE)="","",VLOOKUP($A69,Sheet1!$A$3:$AW$699,5,FALSE)) -> INT | J69: Firmware Revision | K69: 2-Drive | L69: =IF(VLOOKUP($A69,Sheet1!$A$3:$AW$699,7,FALSE)="★","x","") -> x | M69: =IF(VLOOKUP($A69,Sheet1!$A$3:$AW$699,8,FALSE)="▲","x","") | N69: =IF(VLOOKUP($A69,Sheet1!$A$3:$AW$699,9,FALSE)="●","x","") | O69: =IF(VLOOKUP($A69,Sheet1!$A$3:$AW$699,10,FALSE)="■","x","") -> x | P69: =IF(VLOOKUP($A69,Sheet1!$A$3:$AW$699,2,FALSE)="","",VLOOKUP($A69,Sheet1!$A$3:$AW$699,2,FALSE)) -> PN.048
A70: 674 | B70: =IF(VLOOKUP($A70,Sheet1!$A$3:$AW$699,20,FALSE)="","",VLOOKUP($A70,Sheet1!$A$3:$AW$699,20,FALSE)) -> FwSubminorRevision | C70: =IF(VLOOKUP($A70,Sheet1!$A$3:$AW$699,25,FALSE)="","",VLOOKUP($A70,Sheet1!$A$3:$AW$699,25,FALSE)) -> All | D70: =IF(VLOOKUP($A70,Sheet1!$A$3:$AW$699,15,FALSE)="","",VLOOKUP($A70,Sheet1!$A$3:$AW$699,15,FALSE)) -> 0 | E70: =IF(VLOOKUP($A70,Sheet1!$A$3:$AW$699,16,FALSE)="","",VLOOKUP($A70,Sheet1!$A$3:$AW$699,16,FALSE)) -> 2147483647 | F70: =IF(VLOOKUP($A70,Sheet1!$A$3:$AW$699,17,FALSE)="","",VLOOKUP($A70,Sheet1!$A$3:$AW$699,17,FALSE)) -> 0 | G70: =IF(VLOOKUP($A70,Sheet1!$A$3:$AW$699,18,FALSE)="","",VLOOKUP($A70,Sheet1!$A$3:$AW$699,18,FALSE)) | H70: =IF(VLOOKUP($A70,Sheet1!$A$3:$AW$699,19,FALSE)="","",VLOOKUP($A70,Sheet1!$A$3:$AW$699,19,FALSE)) | I70: =IF(VLOOKUP($A70,Sheet1!$A$3:$AW$699,5,FALSE)="","",VLOOKUP($A70,Sheet1!$A$3:$AW$699,5,FALSE)) -> DINT | J70: Firmware Sub-minor Revision | K70: 2-Drive | L70: =IF(VLOOKUP($A70,Sheet1!$A$3:$AW$699,7,FALSE)="★","x","") -> x | M70: =IF(VLOOKUP($A70,Sheet1!$A$3:$AW$699,8,FALSE)="▲","x","") | N70: =IF(VLOOKUP($A70,Sheet1!$A$3:$AW$699,9,FALSE)="●","x","") | O70: =IF(VLOOKUP($A70,Sheet1!$A$3:$AW$699,10,FALSE)="■","x","") -> x | P70: =IF(VLOOKUP($A70,Sheet1!$A$3:$AW$699,2,FALSE)="","",VLOOKUP($A70,Sheet1!$A$3:$AW$699,2,FALSE)) -> PN.049

Sheet 3 - General
A1: Kinetix 5100 Servo Drive Parameters For more information see:
A2: Kinetix 5100 Servo Drive User Manual, publication 2198-UM004
A4: ID | B4: Name | C4: Control Mode | D4: Min. | E4: Max. | F4: Default Value | G4: Precision | H4: Units | I4: Data Type | J4: Comments | K4: Groups | L4: Read-only | M4: Set When Servo Off | N4: Valid After Power Cycle | O4: Volatile Parameter | P4: Parameter Number
A5: 100 | B5: =IF(VLOOKUP($A5,Sheet1!$A$3:$AW$699,20,FALSE)="","",VLOOKUP($A5,Sheet1!$A$3:$AW$699,20,FALSE)) -> DSPFwVer | C5: =IF(VLOOKUP($A5,Sheet1!$A$3:$AW$699,25,FALSE)="","",VLOOKUP($A5,Sheet1!$A$3:$AW$699,25,FALSE)) -> All | D5: =IF(VLOOKUP($A5,Sheet1!$A$3:$AW$699,15,FALSE)="","",VLOOKUP($A5,Sheet1!$A$3:$AW$699,15,FALSE)) -> -32768 | E5: =IF(VLOOKUP($A5,Sheet1!$A$3:$AW$699,16,FALSE)="","",VLOOKUP($A5,Sheet1!$A$3:$AW$699,16,FALSE)) -> 32767 | F5: =IF(VLOOKUP($A5,Sheet1!$A$3:$AW$699,17,FALSE)="","",VLOOKUP($A5,Sheet1!$A$3:$AW$699,17,FALSE)) -> 0 | G5: =IF(VLOOKUP($A5,Sheet1!$A$3:$AW$699,18,FALSE)="","",VLOOKUP($A5,Sheet1!$A$3:$AW$699,18,FALSE)) | H5: =IF(VLOOKUP($A5,Sheet1!$A$3:$AW$699,19,FALSE)="","",VLOOKUP($A5,Sheet1!$A$3:$AW$699,19,FALSE)) | I5: =IF(VLOOKUP($A5,Sheet1!$A$3:$AW$699,5,FALSE)="","",VLOOKUP($A5,Sheet1!$A$3:$AW$699,5,FALSE)) -> INT | J5: DSP Firmware Version High byte = Major version Low byte = Minor version | K5: 3-General | L5: =IF(VLOOKUP($A5,Sheet1!$A$3:$AW$699,7,FALSE)="★","x","") -> x | M5: =IF(VLOOKUP($A5,Sheet1!$A$3:$AW$699,8,FALSE)="▲","x","") | N5: =IF(VLOOKUP($A5,Sheet1!$A$3:$AW$699,9,FALSE)="●","x","") | O5: =IF(VLOOKUP($A5,Sheet1!$A$3:$AW$699,10,FALSE)="■","x","") -> x | P5: =IF(VLOOKUP($A5,Sheet1!$A$3:$AW$699,2,FALSE)="","",VLOOKUP($A5,Sheet1!$A$3:$AW$699,2,FALSE)) -> P0.000
A6: 103 | B6: =IF(VLOOKUP($A6,Sheet1!$A$3:$AW$699,20,FALSE)="","",VLOOKUP($A6,Sheet1!$A$3:$AW$699,20,FALSE)) -> AOMonitorSelection | C6: =IF(VLOOKUP($A6,Sheet1!$A$3:$AW$699,25,FALSE)="","",VLOOKUP($A6,Sheet1!$A$3:$AW$699,25,FALSE)) -> All | D6: =IF(VLOOKUP($A6,Sheet1!$A$3:$AW$699,15,FALSE)="","",VLOOKUP($A6,Sheet1!$A$3:$AW$699,15,FALSE)) -> 0x0000 | E6: =IF(VLOOKUP($A6,Sheet1!$A$3:$AW$699,16,FALSE)="","",VLOOKUP($A6,Sheet1!$A$3:$AW$699,16,FALSE)) -> 0x0077 | F6: =IF(VLOOKUP($A6,Sheet1!$A$3:$AW$699,17,FALSE)="","",VLOOKUP($A6,Sheet1!$A$3:$AW$699,17,FALSE)) -> 0x0000 | G6: =IF(VLOOKUP($A6,Sheet1!$A$3:$AW$699,18,FALSE)="","",VLOOKUP($A6,Sheet1!$A$3:$AW$699,18,FALSE)) | H6: =IF(VLOOKUP($A6,Sheet1!$A$3:$AW$699,19,FALSE)="","",VLOOKUP($A6,Sheet1!$A$3:$AW$699,19,FALSE)) | I6: =IF(VLOOKUP($A6,Sheet1!$A$3:$AW$699,5,FALSE)="","",VLOOKUP($A6,Sheet1!$A$3:$AW$699,5,FALSE)) -> UINT | J6: Analog Output Monitor Selection The operation status of motor can be displayed as analog voltage, such as speed and current. This servo drive provides 2 output channels, MON1 (Y) and MON2 (X). This signal is based on the power ground. The max output voltage (Max.Volt) can be configured to either 8 V or 10 V by ID266(P2.112).bit0. See Analog Monitoring in the user manual. Y (MON1) and X (MON2) 0=Motor speed (±Max.Volt V/Max. speed) 1=Motor torque (±Max.Volt V/Max. torque) 2=Pulse command frequency (+Max.Volt V/4.5Mpps) 3=Speed command (±Max.Volt V/Max. speed command) 4=Torque command (±Max.Volt V/Max. torque command) 5=VBUS voltage (±Max.Volt V/450 V) 6=ID181(P1.101) mV 7=ID182(P1.102) mV UZ Reserved | K6: 3-General | L6: =IF(VLOOKUP($A6,Sheet1!$A$3:$AW$699,7,FALSE)="★","x","") | M6: =IF(VLOOKUP($A6,Sheet1!$A$3:$AW$699,8,FALSE)="▲","x","") | N6: =IF(VLOOKUP($A6,Sheet1!$A$3:$AW$699,9,FALSE)="●","x","") | O6: =IF(VLOOKUP($A6,Sheet1!$A$3:$AW$699,10,FALSE)="■","x","") | P6: =IF(VLOOKUP($A6,Sheet1!$A$3:$AW$699,2,FALSE)="","",VLOOKUP($A6,Sheet1!$A$3:$AW$699,2,FALSE)) -> P0.003
A7: 108 | B7: =IF(VLOOKUP($A7,Sheet1!$A$3:$AW$699,20,FALSE)="","",VLOOKUP($A7,Sheet1!$A$3:$AW$699,20,FALSE)) -> EncoderDataUpdateConfiguration | C7: =IF(VLOOKUP($A7,Sheet1!$A$3:$AW$699,25,FALSE)="","",VLOOKUP($A7,Sheet1!$A$3:$AW$699,25,FALSE)) -> All | D7: =IF(VLOOKUP($A7,Sheet1!$A$3:$AW$699,15,FALSE)="","",VLOOKUP($A7,Sheet1!$A$3:$AW$699,15,FALSE)) -> 0x0000 | E7: =IF(VLOOKUP($A7,Sheet1!$A$3:$AW$699,16,FALSE)="","",VLOOKUP($A7,Sheet1!$A$3:$AW$699,16,FALSE)) -> 0x0002 | F7: =IF(VLOOKUP($A7,Sheet1!$A$3:$AW$699,17,FALSE)="","",VLOOKUP($A7,Sheet1!$A$3:$AW$699,17,FALSE)) -> 0x0000 | G7: =IF(VLOOKUP($A7,Sheet1!$A$3:$AW$699,18,FALSE)="","",VLOOKUP($A7,Sheet1!$A$3:$AW$699,18,FALSE)) | H7: =IF(VLOOKUP($A7,Sheet1!$A$3:$AW$699,19,FALSE)="","",VLOOKUP($A7,Sheet1!$A$3:$AW$699,19,FALSE)) | I7: =IF(VLOOKUP($A7,Sheet1!$A$3:$AW$699,5,FALSE)="","",VLOOKUP($A7,Sheet1!$A$3:$AW$699,5,FALSE)) -> UINT | J7: Encoder Data Update Configuration See Reading the Absolute Position with Communication in the user manual. X: Command processing 0=Not applicable 1=Update the encoder data of ID109…ID111 (P0.050…P0.052) 2=Update ID109…ID111 (P0.050…P0.052) and clear the position error. When the command takes effect, the motor's current position will be set as the terminal point of the position command. | K7: 3-General | L7: =IF(VLOOKUP($A7,Sheet1!$A$3:$AW$699,7,FALSE)="★","x","") | M7: =IF(VLOOKUP($A7,Sheet1!$A$3:$AW$699,8,FALSE)="▲","x","") | N7: =IF(VLOOKUP($A7,Sheet1!$A$3:$AW$699,9,FALSE)="●","x","") | O7: =IF(VLOOKUP($A7,Sheet1!$A$3:$AW$699,10,FALSE)="■","x","") -> x | P7: =IF(VLOOKUP($A7,Sheet1!$A$3:$AW$699,2,FALSE)="","",VLOOKUP($A7,Sheet1!$A$3:$AW$699,2,FALSE)) -> P0.049
A8: 112 | B8: =IF(VLOOKUP($A8,Sheet1!$A$3:$AW$699,20,FALSE)="","",VLOOKUP($A8,Sheet1!$A$3:$AW$699,20,FALSE)) -> SystemVariableMonitorFilterTime | C8: =IF(VLOOKUP($A8,Sheet1!$A$3:$AW$699,25,FALSE)="","",VLOOKUP($A8,Sheet1!$A$3:$AW$699,25,FALSE)) -> All | D8: =IF(VLOOKUP($A8,Sheet1!$A$3:$AW$699,15,FALSE)="","",VLOOKUP($A8,Sheet1!$A$3:$AW$699,15,FALSE)) -> 0x0000 | E8: =IF(VLOOKUP($A8,Sheet1!$A$3:$AW$699,16,FALSE)="","",VLOOKUP($A8,Sheet1!$A$3:$AW$699,16,FALSE)) -> 0x000F | F8: =IF(VLOOKUP($A8,Sheet1!$A$3:$AW$699,17,FALSE)="","",VLOOKUP($A8,Sheet1!$A$3:$AW$699,17,FALSE)) -> 0x0000 | G8: =IF(VLOOKUP($A8,Sheet1!$A$3:$AW$699,18,FALSE)="","",VLOOKUP($A8,Sheet1!$A$3:$AW$699,18,FALSE)) | H8: =IF(VLOOKUP($A8,Sheet1!$A$3:$AW$699,19,FALSE)="","",VLOOKUP($A8,Sheet1!$A$3:$AW$699,19,FALSE)) -> ms | I8: =IF(VLOOKUP($A8,Sheet1!$A$3:$AW$699,5,FALSE)="","",VLOOKUP($A8,Sheet1!$A$3:$AW$699,5,FALSE)) -> UINT | J8: System Variable Monitor Filter Time See Description of System Variable Monitoring in the user manual. X: First filter time, see ID113 (P0.054) and ID114 (P0.055) Y, Z, U: Reserved Note: 0 = 1 ms, 1 = 2 ms, 2 = 3 ms, … , F = 16 ms. | K8: 3-General | L8: =IF(VLOOKUP($A8,Sheet1!$A$3:$AW$699,7,FALSE)="★","x","") | M8: =IF(VLOOKUP($A8,Sheet1!$A$3:$AW$699,8,FALSE)="▲","x","") | N8: =IF(VLOOKUP($A8,Sheet1!$A$3:$AW$699,9,FALSE)="●","x","") | O8: =IF(VLOOKUP($A8,Sheet1!$A$3:$AW$699,10,FALSE)="■","x","") | P8: =IF(VLOOKUP($A8,Sheet1!$A$3:$AW$699,2,FALSE)="","",VLOOKUP($A8,Sheet1!$A$3:$AW$699,2,FALSE)) -> P0.053
